Workbook

Sheet CONTROL FLOTA
A1: CONTROL FLOTA - AGRÍCOLA SAN JOSÉ | R1: FECHA ACTUAL:
R2: =TODAY() -> 46211
A4: FLOTA TOTAL | C4: OPERATIVAS | E4: EN MANTENCIÓN | G4: ARRIENDO | I4: FUERA DE SERVICIO | K4: RT VENCIDAS | M4: RT PRÓX. 30 DÍAS | O4: GASES VENCIDOS | Q4: GASES PRÓX. 30 DÍAS | S4: CAMBIO ACEITE PRÓX.
A5: =COUNTA(DATOS!$H$2:$H$22) -> 21 | C5: =COUNTIF(DATOS!$R$2:$R$22,"OPERATIVA") -> 17 | E5: =COUNTIF(DATOS!$R$2:$R$22,"EN MANTENCIÓN") -> 1 | G5: =COUNTIF(DATOS!$R$2:$R$22,"ARRIENDO") -> 2 | I5: =COUNTIF(DATOS!$R$2:$R$22,"FUERA DE SERVICIO") -> 1 | K5: =COUNTIF(DATOS!$M$2:$M$22,"<0") -> 4 | M5: =COUNTIFS(DATOS!$M$2:$M$22,">=0",DATOS!$M$2:$M$22,"<=30") -> 0 | O5: =COUNTIF(DATOS!$O$2:$O$22,"<0") -> 4 | Q5: =COUNTIFS(DATOS!$O$2:$O$22,">=0",DATOS!$O$2:$O$22,"<=30") -> 0 | S5: =COUNTIFS(DATOS!$Q$2:$Q$22,">=0",DATOS!$Q$2:$Q$22,"<=500") -> 0
A6: Unidades | C6: Unidades | E6: Unidades | G6: Unidades | I6: Unidades | K6: Crítico | M6: Seguimiento | O6: Crítico | Q6: Seguimiento | S6: < 500 km
A8: GASTO COMBUSTIBLE | E8: GASTO MANTENCIÓN | I8: COSTO TOTAL | M8: COSTO PROMEDIO POR KM | Q8: KM TOTALES FLOTA
A9: =SUM(DATOS!$S$2:$S$22) -> 3779528.6 | E9: =SUM(DATOS!$T$2:$T$22) -> 1448768 | I9: =SUM(DATOS!$U$2:$U$22) -> 5228296.6 | M9: =IFERROR(AVERAGEIF(DATOS!$V$2:$V$22,">0"),0) -> 175.09566 | Q9: =SUM(DATOS!$K$2:$K$22) -> 749559.24
A10: Total año | E10: Total año | I10: Total año | M10: Promedio general | Q10: Total acumulado
A12: TOP 5 MAYOR COSTO MANTENCIÓN | G12: TOP 5 MAYOR COSTO TOTAL | L12: TOP 5 GASTO COMBUSTIBLE | Q12: DISTRIBUCIÓN POR ESTADO
A13: N | B13: Alerta | C13: Unidades | D13: Detalle | E13: Estado | G13: NOMBRE | H13: Costo total | I13: Costo | L13: N° | M13: Patente | N13: Gasto combustible | Q13: Maquina | R13: Prioridad | S13: Estado
A14: 1 | B14: =IFERROR(INDEX(DATOS!$C$2:$C$22,MATCH(LARGE(DATOS!$T$2:$T$22,1),DATOS!$T$2:$T$22,0)),"") -> SERGIO ROJAS | C14: =IFERROR(LARGE(DATOS!$T$2:$T$22,1),0) -> 270796 | G14: 1 | H14: =IFERROR(INDEX(DATOS!$C$2:$C$22,MATCH(LARGE(DATOS!$U$2:$U$22,1),DATOS!$U$2:$U$22,0)),"") -> RODRIGO SALINAS | I14: =IFERROR(LARGE(DATOS!$U$2:$U$22,1),0) -> 670717.66 | L14: 1 | M14: =IFERROR(INDEX(DATOS!$C$2:$C$22,MATCH(LARGE(DATOS!$S$2:$S$22,1),DATOS!$S$2:$S$22,0)),"") -> RODRIGO SALINAS | N14: =IFERROR(LARGE(DATOS!$S$2:$S$22,1),0) -> 632917.66 | Q14: =IFERROR(INDEX(DATOS!$C$2:$C$22,MATCH(SMALL(DATOS!$Y$2:$Y$22,1),DATOS!$Y$2:$Y$22,0)),"") -> SSANYONG | R14: =SMALL(DATOS!Y:Y,1) -> 1.022 | S14: =_xlfn.XLOOKUP(Q14,DATOS!C:C,DATOS!X:X) -> Fuera de servicio
A15: 2 | B15: =IFERROR(INDEX(DATOS!$C$2:$C$22,MATCH(LARGE(DATOS!$T$2:$T$22,2),DATOS!$T$2:$T$22,0)),"") -> CAMPO CERRILLOS | C15: =IFERROR(LARGE(DATOS!$T$2:$T$22,2),0) -> 155599 | G15: 2 | H15: =IFERROR(INDEX(DATOS!$C$2:$C$22,MATCH(LARGE(DATOS!$U$2:$U$22,2),DATOS!$U$2:$U$22,0)),"") -> SERGIO ROJAS | I15: =IFERROR(LARGE(DATOS!$U$2:$U$22,2),0) -> 526673.05 | L15: 2 | M15: =IFERROR(INDEX(DATOS!$C$2:$C$22,MATCH(LARGE(DATOS!$S$2:$S$22,2),DATOS!$S$2:$S$22,0)),"") -> VG PIÑALEO | N15: =IFERROR(LARGE(DATOS!$S$2:$S$22,2),0) -> 371846.41 | Q15: =IFERROR(INDEX(DATOS!$C$2:$C$22,MATCH(SMALL(DATOS!$Y$2:$Y$22,2),DATOS!$Y$2:$Y$22,0)),"") -> T4 | R15: =SMALL(DATOS!Y:Y,2) -> 2.013 | S15: =_xlfn.XLOOKUP(Q15,DATOS!C:C,DATOS!X:X) -> En mantención
A16: 3 | B16: =IFERROR(INDEX(DATOS!$C$2:$C$22,MATCH(LARGE(DATOS!$T$2:$T$22,3),DATOS!$T$2:$T$22,0)),"") -> VG GERARDO | C16: =IFERROR(LARGE(DATOS!$T$2:$T$22,3),0) -> 135674 | G16: 3 | H16: =IFERROR(INDEX(DATOS!$C$2:$C$22,MATCH(LARGE(DATOS!$U$2:$U$22,3),DATOS!$U$2:$U$22,0)),"") -> VG GERARDO | I16: =IFERROR(LARGE(DATOS!$U$2:$U$22,3),0) -> 477038.95 | L16: 3 | M16: =IFERROR(INDEX(DATOS!$C$2:$C$22,MATCH(LARGE(DATOS!$S$2:$S$22,3),DATOS!$S$2:$S$22,0)),"") -> VG GERARDO | N16: =IFERROR(LARGE(DATOS!$S$2:$S$22,3),0) -> 341364.95 | Q16: =IFERROR(INDEX(DATOS!$C$2:$C$22,MATCH(SMALL(DATOS!$Y$2:$Y$22,3),DATOS!$Y$2:$Y$22,0)),"") -> CAMPO PAINE | R16: =SMALL(DATOS!Y:Y,3) -> 3.008 | S16: =_xlfn.XLOOKUP(Q16,DATOS!C:C,DATOS!X:X) -> RT vencida
A17: 4 | B17: =IFERROR(INDEX(DATOS!$C$2:$C$22,MATCH(LARGE(DATOS!$T$2:$T$22,4),DATOS!$T$2:$T$22,0)),"") -> CAMPO RULO | C17: =IFERROR(LARGE(DATOS!$T$2:$T$22,4),0) -> 120599 | G17: 4 | H17: =IFERROR(INDEX(DATOS!$C$2:$C$22,MATCH(LARGE(DATOS!$U$2:$U$22,4),DATOS!$U$2:$U$22,0)),"") -> CAMPO CERRILLOS | I17: =IFERROR(LARGE(DATOS!$U$2:$U$22,4),0) -> 475079.68 | L17: 4 | M17: =IFERROR(INDEX(DATOS!$C$2:$C$22,MATCH(LARGE(DATOS!$S$2:$S$22,4),DATOS!$S$2:$S$22,0)),"") -> CAMPO CERRILLOS | N17: =IFERROR(LARGE(DATOS!$S$2:$S$22,4),0) -> 319480.68 | Q17: =IFERROR(INDEX(DATOS!$C$2:$C$22,MATCH(SMALL(DATOS!$Y$2:$Y$22,4),DATOS!$Y$2:$Y$22,0)),"") -> T12 | R17: =SMALL(DATOS!Y:Y,4) -> 3.016 | S17: =_xlfn.XLOOKUP(Q17,DATOS!C:C,DATOS!X:X) -> RT vencida
A18: 5 | B18: =IFERROR(INDEX(DATOS!$C$2:$C$22,MATCH(LARGE(DATOS!$T$2:$T$22,5),DATOS!$T$2:$T$22,0)),"") -> CAMPO PAINE | C18: =IFERROR(LARGE(DATOS!$T$2:$T$22,5),0) -> 107800 | G18: 5 | H18: =IFERROR(INDEX(DATOS!$C$2:$C$22,MATCH(LARGE(DATOS!$U$2:$U$22,5),DATOS!$U$2:$U$22,0)),"") -> VG PIÑALEO | I18: =IFERROR(LARGE(DATOS!$U$2:$U$22,5),0) -> 442646.41 | L18: 5 | M18: =IFERROR(INDEX(DATOS!$C$2:$C$22,MATCH(LARGE(DATOS!$S$2:$S$22,5),DATOS!$S$2:$S$22,0)),"") -> GONZALO GUERRERO | N18: =IFERROR(LARGE(DATOS!$S$2:$S$22,5),0) -> 264639.02 | Q18: =IFERROR(INDEX(DATOS!$C$2:$C$22,MATCH(SMALL(DATOS!$Y$2:$Y$22,5),DATOS!$Y$2:$Y$22,0)),"") -> T11 | R18: =SMALL(DATOS!Y:Y,5) -> 3.02 | S18: =_xlfn.XLOOKUP(Q18,DATOS!C:C,DATOS!X:X) -> RT vencida
A20: CONTROL OPERATIVO ORDENADO POR PRIORIDAD
A21: Prioridad | B21: Estado | C21: Tipo | D21: Patente | E21: Marca | F21: Modelo | G21: Año | H21: Responsable | I21: Ubicación | J21: KM Actual | K21: RT días | L21: Gases días | M21: Cambio aceite (km) | N21: Gasto Comb. | O21: Gasto Mant. | P21: Costo Total | Q21: Costo por KM | R21: Maquinaria | S21: Ubic. | T21: Nota
A22: =IF(DATOS!$R$22="FUERA DE SERVICIO",1,IF(DATOS!$R$22="EN MANTENCIÓN",2,IF(OR(IFERROR(DATOS!$M$22<0,FALSE),IFERROR(DATOS!$O$22<0,FALSE)),3,IF(OR(IFERROR(AND(DATOS!$M$22>=0,DATOS!$M$22<=30),FALSE),IFERROR(AND(DATOS!$O$22>=0,DATOS!$O$22<=30),FALSE)),4,IF(IFERROR(AND(DATOS!$Q$22>=0,DATOS!$Q$22<=10000),FALSE),5,6))))) -> 1 | B22: =DATOS!R22 -> FUERA DE SERVICIO | C22: =DATOS!A22 -> Vehiculo | D22: =DATOS!H22 -> JKVT20 | E22: =DATOS!E22 -> Ssangyong | F22: =DATOS!F22 -> Actyon | G22: =DATOS!G22 -> 2017 | H22: =DATOS!C22 -> SSANYONG | I22: =DATOS!B22 -> Rulo | J22: =DATOS!K22 -> 0 | K22: =DATOS!M22 -> -522 | L22: =DATOS!O22 -> -522 | M22: =DATOS!Q22 -> - | N22: =DATOS!S22 -> 0 | O22: =DATOS!T22 -> 25300 | P22: =DATOS!U22 -> 25300 | Q22: =DATOS!V22 -> - | R22: =DATOS!D22 -> CMTA0 | S22: =DATOS!B22 -> Rulo
A23: =IF(DATOS!$R$13="FUERA DE SERVICIO",1,IF(DATOS!$R$13="EN MANTENCIÓN",2,IF(OR(IFERROR(DATOS!$M$13<0,FALSE),IFERROR(DATOS!$O$13<0,FALSE)),3,IF(OR(IFERROR(AND(DATOS!$M$13>=0,DATOS!$M$13<=30),FALSE),IFERROR(AND(DATOS!$O$13>=0,DATOS!$O$13<=30),FALSE)),4,IF(IFERROR(AND(DATOS!$Q$13>=0,DATOS!$Q$13<=10000),FALSE),5,6))))) -> 2 | B23: =DATOS!R13 -> EN MANTENCIÓN | C23: =DATOS!A13 -> TRACTOR | D23: =DATOS!H13 -> CYPX-61 | E23: =DATOS!E13 -> New Holland | F23: =DATOS!F13 -> T4030F | G23: =DATOS!G13 -> 2011 | H23: =DATOS!C13 -> T4 | I23: =DATOS!B13 -> Rulo | J23: =DATOS!K13 -> 0 | K23: =DATOS!M13 -> 786 | L23: =DATOS!O13 -> 786 | M23: =DATOS!Q13 -> - | N23: =DATOS!S13 -> 125408.42 | O23: =DATOS!T13 -> 37800 | P23: =DATOS!U13 -> 163208.42 | Q23: =DATOS!V13 -> 140.86206 | R23: =DATOS!D13 -> T4 | S23: =DATOS!B13 -> Rulo
A24: =IF(DATOS!$R$19="FUERA DE SERVICIO",1,IF(DATOS!$R$19="EN MANTENCIÓN",2,IF(OR(IFERROR(DATOS!$M$19<0,FALSE),IFERROR(DATOS!$O$19<0,FALSE)),3,IF(OR(IFERROR(AND(DATOS!$M$19>=0,DATOS!$M$19<=30),FALSE),IFERROR(AND(DATOS!$O$19>=0,DATOS!$O$19<=30),FALSE)),4,IF(IFERROR(AND(DATOS!$Q$19>=0,DATOS!$Q$19<=10000),FALSE),5,6))))) -> 6 | B24: =DATOS!R19 -> OPERATIVA | C24: =DATOS!A19 -> TRACTOR | D24: =DATOS!H19 -> JYJT-41 | E24: =DATOS!E19 -> Same | F24: =DATOS!F19 -> FRUTTETO3 75 | G24: =DATOS!G19 -> 2017 | H24: =DATOS!C19 -> T8 | I24: =DATOS!B19 -> Cerrillos | J24: =DATOS!K19 -> 0 | K24: =DATOS!M19 -> 85 | L24: =DATOS!O19 -> 85 | M24: =DATOS!Q19 -> - | N24: =DATOS!S19 -> 71373.428 | O24: =DATOS!T19 -> 37800 | P24: =DATOS!U19 -> 109173.43 | Q24: =DATOS!V19 -> 116.99953 | R24: =DATOS!D19 -> T8 | S24: =DATOS!B19 -> Cerrillos
A25: =IF(DATOS!$R$4="FUERA DE SERVICIO",1,IF(DATOS!$R$4="EN MANTENCIÓN",2,IF(OR(IFERROR(DATOS!$M$4<0,FALSE),IFERROR(DATOS!$O$4<0,FALSE)),3,IF(OR(IFERROR(AND(DATOS!$M$4>=0,DATOS!$M$4<=30),FALSE),IFERROR(AND(DATOS!$O$4>=0,DATOS!$O$4<=30),FALSE)),4,IF(IFERROR(AND(DATOS!$Q$4>=0,DATOS!$Q$4<=10000),FALSE),5,6))))) -> 5 | B25: =DATOS!R4 -> OPERATIVA | C25: =DATOS!A4 -> Vehiculo | D25: =DATOS!H4 -> KCTL47 | E25: =DATOS!E4 -> Volkswagen | F25: =DATOS!F4 -> Saveiro | G25: =DATOS!G4 -> 2018 | H25: =DATOS!C4 -> VG GERARDO | I25: =DATOS!B4 -> Rulo | J25: =DATOS!K4 -> 113508.42 | K25: =DATOS!M4 -> 177 | L25: =DATOS!O4 -> 177 | M25: =DATOS!Q4 -> 4239.58 | N25: =DATOS!S4 -> 341364.95 | O25: =DATOS!T4 -> 135674 | P25: =DATOS!U4 -> 477038.95 | Q25: =DATOS!V4 -> 240.08362 | R25: =DATOS!D4 -> CMTA04 | S25: =DATOS!B4 -> Rulo
A26: =IF(DATOS!$R$10="FUERA DE SERVICIO",1,IF(DATOS!$R$10="EN MANTENCIÓN",2,IF(OR(IFERROR(DATOS!$M$10<0,FALSE),IFERROR(DATOS!$O$10<0,FALSE)),3,IF(OR(IFERROR(AND(DATOS!$M$10>=0,DATOS!$M$10<=30),FALSE),IFERROR(AND(DATOS!$O$10>=0,DATOS!$O$10<=30),FALSE)),4,IF(IFERROR(AND(DATOS!$Q$10>=0,DATOS!$Q$10<=10000),FALSE),5,6))))) -> 5 | B26: =DATOS!R10 -> OPERATIVA | C26: =DATOS!A10 -> Vehiculo | D26: =DATOS!H10 -> KCTL48 | E26: =DATOS!E10 -> Volkswagen | F26: =DATOS!F10 -> Saveiro | G26: =DATOS!G10 -> 2018 | H26: =DATOS!C10 -> VG CERRILLOS | I26: =DATOS!B10 -> Cerrillos | J26: =DATOS!K10 -> 106758.78 | K26: =DATOS!M10 -> 116 | L26: =DATOS!O10 -> 116 | M26: =DATOS!Q10 -> 1241.22 | N26: =DATOS!S10 -> 206031.64 | O26: =DATOS!T10 -> 70800 | P26: =DATOS!U10 -> 276831.64 | Q26: =DATOS!V10 -> 196.61477 | R26: =DATOS!D10 -> CMTA05 | S26: =DATOS!B10 -> Cerrillos
A27: =IF(DATOS!$R$20="FUERA DE SERVICIO",1,IF(DATOS!$R$20="EN MANTENCIÓN",2,IF(OR(IFERROR(DATOS!$M$20<0,FALSE),IFERROR(DATOS!$O$20<0,FALSE)),3,IF(OR(IFERROR(AND(DATOS!$M$20>=0,DATOS!$M$20<=30),FALSE),IFERROR(AND(DATOS!$O$20>=0,DATOS!$O$20<=30),FALSE)),4,IF(IFERROR(AND(DATOS!$Q$20>=0,DATOS!$Q$20<=10000),FALSE),5,6))))) -> 3 | B27: =DATOS!R20 -> OPERATIVA | C27: =DATOS!A20 -> TRACTOR | D27: =DATOS!H20 -> LXFB96 | E27: =DATOS!E20 -> John Deere | F27: =DATOS!F20 -> 5085GL | G27: =DATOS!G20 -> 2021 | H27: =DATOS!C20 -> T11 | I27: =DATOS!B20 -> Cerrillos | J27: =DATOS!K20 -> 0 | K27: =DATOS!M20 -> -310 | L27: =DATOS!O20 -> -310 | M27: =DATOS!Q20 -> - | N27: =DATOS!S20 -> 62267.847 | O27: =DATOS!T20 -> 37800 | P27: =DATOS!U20 -> 100067.85 | Q27: =DATOS!V20 -> 111.39691 | R27: =DATOS!D20 -> T11 | S27: =DATOS!B20 -> Cerrillos
A28: =IF(DATOS!$R$16="FUERA DE SERVICIO",1,IF(DATOS!$R$16="EN MANTENCIÓN",2,IF(OR(IFERROR(DATOS!$M$16<0,FALSE),IFERROR(DATOS!$O$16<0,FALSE)),3,IF(OR(IFERROR(AND(DATOS!$M$16>=0,DATOS!$M$16<=30),FALSE),IFERROR(AND(DATOS!$O$16>=0,DATOS!$O$16<=30),FALSE)),4,IF(IFERROR(AND(DATOS!$Q$16>=0,DATOS!$Q$16<=10000),FALSE),5,6))))) -> 3 | B28: =DATOS!R16 -> OPERATIVA | C28: =DATOS!A16 -> TRACTOR | D28: =DATOS!H16 -> LZPF54 | E28: =DATOS!E16 -> John Deere | F28: =DATOS!F16 -> 5085GL | G28: =DATOS!G16 -> 2021 | H28: =DATOS!C16 -> T12 | I28: =DATOS!B16 -> Cerrillos | J28: =DATOS!K16 -> 0 | K28: =DATOS!M16 -> -310 | L28: =DATOS!O16 -> -310 | M28: =DATOS!Q16 -> - | N28: =DATOS!S16 -> 74638.147 | O28: =DATOS!T16 -> 37800 | P28: =DATOS!U16 -> 112438.15 | Q28: =DATOS!V16 -> 120.68711 | R28: =DATOS!D16 -> T12 | S28: =DATOS!B16 -> Cerrillos
A29: =IF(DATOS!$R$8="FUERA DE SERVICIO",1,IF(DATOS!$R$8="EN MANTENCIÓN",2,IF(OR(IFERROR(DATOS!$M$8<0,FALSE),IFERROR(DATOS!$O$8<0,FALSE)),3,IF(OR(IFERROR(AND(DATOS!$M$8>=0,DATOS!$M$8<=30),FALSE),IFERROR(AND(DATOS!$O$8>=0,DATOS!$O$8<=30),FALSE)),4,IF(IFERROR(AND(DATOS!$Q$8>=0,DATOS!$Q$8<=10000),FALSE),5,6))))) -> 3 | B29: =DATOS!R8 -> OPERATIVA | C29: =DATOS!A8 -> Vehiculo | D29: =DATOS!H8 -> GRTF64 | E29: =DATOS!E8 -> Mitsubishi | F29: =DATOS!F8 -> L200 Katana | G29: =DATOS!G8 -> 2015 | H29: =DATOS!C8 -> CAMPO PAINE | I29: =DATOS!B8 -> Paine | J29: =DATOS!K8 -> 199236 | K29: =DATOS!M8 -> -7 | L29: =DATOS!O8 -> -7 | M29: =DATOS!Q8 -> 6764 | N29: =DATOS!S8 -> 220296.76 | O29: =DATOS!T8 -> 107800 | P29: =DATOS!U8 -> 328096.76 | Q29: =DATOS!V8 -> 146.26282 | R29: =DATOS!D8 -> CMTA01 | S29: =DATOS!B8 -> Paine
A30: =IF(DATOS!$R$3="FUERA DE SERVICIO",1,IF(DATOS!$R$3="EN MANTENCIÓN",2,IF(OR(IFERROR(DATOS!$M$3<0,FALSE),IFERROR(DATOS!$O$3<0,FALSE)),3,IF(OR(IFERROR(AND(DATOS!$M$3>=0,DATOS!$M$3<=30),FALSE),IFERROR(AND(DATOS!$O$3>=0,DATOS!$O$3<=30),FALSE)),4,IF(IFERROR(AND(DATOS!$Q$3>=0,DATOS!$Q$3<=10000),FALSE),5,6))))) -> 6 | B30: =DATOS!R3 -> OPERATIVA | C30: =DATOS!A3 -> Vehiculo | D30: =DATOS!H3 -> KCTL49 | E30: =DATOS!E3 -> Volkswagen | F30: =DATOS!F3 -> Saveiro | G30: =DATOS!G3 -> 2018 | H30: =DATOS!C3 -> VG PIÑALEO | I30: =DATOS!B3 -> Rulo | J30: =DATOS!K3 -> 111468.22 | K30: =DATOS!M3 -> 85 | L30: =DATOS!O3 -> 55 | M30: =DATOS!Q3 -> -568.22 | N30: =DATOS!S3 -> 371846.41 | O30: =DATOS!T3 -> 70800 | P30: =DATOS!U3 -> 442646.41 | Q30: =DATOS!V3 -> 247.96312 | R30: =DATOS!D3 -> CMTA03 | S30: =DATOS!B3 -> Rulo
A31: =IF(DATOS!$R$7="FUERA DE SERVICIO",1,IF(DATOS!$R$7="EN MANTENCIÓN",2,IF(OR(IFERROR(DATOS!$M$7<0,FALSE),IFERROR(DATOS!$O$7<0,FALSE)),3,IF(OR(IFERROR(AND(DATOS!$M$7>=0,DATOS!$M$7<=30),FALSE),IFERROR(AND(DATOS!$O$7>=0,DATOS!$O$7<=30),FALSE)),4,IF(IFERROR(AND(DATOS!$Q$7>=0,DATOS!$Q$7<=10000),FALSE),5,6))))) -> 5 | B31: =DATOS!R7 -> OPERATIVA | C31: =DATOS!A7 -> Vehiculo | D31: =DATOS!H7 -> KBVX10 | E31: =DATOS!E7 -> Nissan | F31: =DATOS!F7 -> NP300 | G31: =DATOS!G7 -> 2018 | H31: =DATOS!C7 -> SERGIO ROJAS | I31: =DATOS!B7 -> Cerrillos | J31: =DATOS!K7 -> 172278.82 | K31: =DATOS!M7 -> 208 | L31: =DATOS!O7 -> 208 | M31: =DATOS!Q7 -> 7940.18 | N31: =DATOS!S7 -> 255877.05 | O31: =DATOS!T7 -> 270796 | P31: =DATOS!U7 -> 526673.05 | Q31: =DATOS!V7 -> 477.26211 | R31: =DATOS!D7 -> CMTA02 | S31: =DATOS!B7 -> Cerrillos
A32: =IF(DATOS!$R$6="FUERA DE SERVICIO",1,IF(DATOS!$R$6="EN MANTENCIÓN",2,IF(OR(IFERROR(DATOS!$M$6<0,FALSE),IFERROR(DATOS!$O$6<0,FALSE)),3,IF(OR(IFERROR(AND(DATOS!$M$6>=0,DATOS!$M$6<=30),FALSE),IFERROR(AND(DATOS!$O$6>=0,DATOS!$O$6<=30),FALSE)),4,IF(IFERROR(AND(DATOS!$Q$6>=0,DATOS!$Q$6<=10000),FALSE),5,6))))) -> 6 | B32: =DATOS!R6 -> ARRIENDO | C32: =DATOS!A6 -> Vehiculo | D32: =DATOS!H6 -> RHYH16 | E32: =DATOS!E6 -> Nissan | F32: =DATOS!F6 -> Navara DC SE 2,3D | G32: =DATOS!G6 -> 2022 | H32: =DATOS!C6 -> GONZALO GUERRERO | I32: =DATOS!B6 -> Paine | J32: =DATOS!K6 -> 0 | K32: =DATOS!M6 -> - | L32: =DATOS!O6 -> - | M32: =DATOS!Q6 -> - | N32: =DATOS!S6 -> 264639.02 | O32: =DATOS!T6 -> 37800 | P32: =DATOS!U6 -> 302439.02 | Q32: =DATOS!V6 -> 150.38263 | R32: =DATOS!D6 -> CMTA08 | S32: =DATOS!B6 -> Paine
A33: =IF(DATOS!$R$2="FUERA DE SERVICIO",1,IF(DATOS!$R$2="EN MANTENCIÓN",2,IF(OR(IFERROR(DATOS!$M$2<0,FALSE),IFERROR(DATOS!$O$2<0,FALSE)),3,IF(OR(IFERROR(AND(DATOS!$M$2>=0,DATOS!$M$2<=30),FALSE),IFERROR(AND(DATOS!$O$2>=0,DATOS!$O$2<=30),FALSE)),4,IF(IFERROR(AND(DATOS!$Q$2>=0,DATOS!$Q$2<=10000),FALSE),5,6))))) -> 6 | B33: =DATOS!R2 -> ARRIENDO | C33: =DATOS!A2 -> Vehiculo | D33: =DATOS!H2 -> RHYH23 | E33: =DATOS!E2 -> Nissan | F33: =DATOS!F2 -> Navara DC SE 2,3D | G33: =DATOS!G2 -> 2022 | H33: =DATOS!C2 -> RODRIGO SALINAS | I33: =DATOS!B2 -> Rulo | J33: =DATOS!K2 -> 0 | K33: =DATOS!M2 -> - | L33: =DATOS!O2 -> - | M33: =DATOS!Q2 -> - | N33: =DATOS!S2 -> 632917.66 | O33: =DATOS!T2 -> 37800 | P33: =DATOS!U2 -> 670717.66 | Q33: =DATOS!V2 -> 141.4142 | R33: =DATOS!D2 -> CMTA07 | S33: =DATOS!B2 -> Rulo
A34: =IF(DATOS!$R$15="FUERA DE SERVICIO",1,IF(DATOS!$R$15="EN MANTENCIÓN",2,IF(OR(IFERROR(DATOS!$M$15<0,FALSE),IFERROR(DATOS!$O$15<0,FALSE)),3,IF(OR(IFERROR(AND(DATOS!$M$15>=0,DATOS!$M$15<=30),FALSE),IFERROR(AND(DATOS!$O$15>=0,DATOS!$O$15<=30),FALSE)),4,IF(IFERROR(AND(DATOS!$Q$15>=0,DATOS!$Q$15<=10000),FALSE),5,6))))) -> 6 | B34: =DATOS!R15 -> OPERATIVA | C34: =DATOS!A15 -> TRACTOR | D34: =DATOS!H15 -> CYPX-60 | E34: =DATOS!E15 -> New Holland | F34: =DATOS!F15 -> T4030FWD | G34: =DATOS!G15 -> 2011 | H34: =DATOS!C15 -> T5 | I34: =DATOS!B15 -> Rulo | J34: =DATOS!K15 -> 0 | K34: =DATOS!M15 -> 786 | L34: =DATOS!O15 -> 786 | M34: =DATOS!Q15 -> - | N34: =DATOS!S15 -> 76049.322 | O34: =DATOS!T15 -> 37800 | P34: =DATOS!U15 -> 113849.32 | Q34: =DATOS!V15 -> 115.1121 | R34: =DATOS!D15 -> T5 | S34: =DATOS!B15 -> Rulo
A35: =IF(DATOS!$R$17="FUERA DE SERVICIO",1,IF(DATOS!$R$17="EN MANTENCIÓN",2,IF(OR(IFERROR(DATOS!$M$17<0,FALSE),IFERROR(DATOS!$O$17<0,FALSE)),3,IF(OR(IFERROR(AND(DATOS!$M$17>=0,DATOS!$M$17<=30),FALSE),IFERROR(AND(DATOS!$O$17>=0,DATOS!$O$17<=30),FALSE)),4,IF(IFERROR(AND(DATOS!$Q$17>=0,DATOS!$Q$17<=10000),FALSE),5,6))))) -> 6 | B35: =DATOS!R17 -> OPERATIVA | C35: =DATOS!A17 -> TRACTOR | D35: =DATOS!H17 -> FDHD-57 | E35: =DATOS!E17 -> New Holland | F35: =DATOS!F17 -> T4040F W FRUTER | G35: =DATOS!G17 -> 2013 | H35: =DATOS!C17 -> T6 | I35: =DATOS!B17 -> Rulo | J35: =DATOS!K17 -> 0 | K35: =DATOS!M17 -> 786 | L35: =DATOS!O17 -> 786 | M35: =DATOS!Q17 -> - | N35: =DATOS!S17 -> 74143.735 | O35: =DATOS!T17 -> 37800 | P35: =DATOS!U17 -> 111943.73 | Q35: =DATOS!V17 -> 124.67561 | R35: =DATOS!D17 -> T6 | S35: =DATOS!B17 -> Rulo
A36: =IF(DATOS!$R$21="FUERA DE SERVICIO",1,IF(DATOS!$R$21="EN MANTENCIÓN",2,IF(OR(IFERROR(DATOS!$M$21<0,FALSE),IFERROR(DATOS!$O$21<0,FALSE)),3,IF(OR(IFERROR(AND(DATOS!$M$21>=0,DATOS!$M$21<=30),FALSE),IFERROR(AND(DATOS!$O$21>=0,DATOS!$O$21<=30),FALSE)),4,IF(IFERROR(AND(DATOS!$Q$21>=0,DATOS!$Q$21<=10000),FALSE),5,6))))) -> 6 | B36: =DATOS!R21 -> OPERATIVA | C36: =DATOS!A21 -> TRACTOR | D36: =DATOS!H21 -> JXXZ-54 | E36: =DATOS!E21 -> Same | F36: =DATOS!F21 -> FRUTTETO 3 75 DT 46 NA | G36: =DATOS!G21 -> 2018 | H36: =DATOS!C21 -> T9 | I36: =DATOS!B21 -> Cerrillos | J36: =DATOS!K21 -> 0 | K36: =DATOS!M21 -> 85 | L36: =DATOS!O21 -> 85 | M36: =DATOS!Q21 -> - | N36: =DATOS!S21 -> 29370.455 | O36: =DATOS!T21 -> 37800 | P36: =DATOS!U21 -> 67170.455 | Q36: =DATOS!V21 -> 110.89907 | R36: =DATOS!D21 -> T9 | S36: =DATOS!B21 -> Cerrillos
A37: =IF(DATOS!$R$14="FUERA DE SERVICIO",1,IF(DATOS!$R$14="EN MANTENCIÓN",2,IF(OR(IFERROR(DATOS!$M$14<0,FALSE),IFERROR(DATOS!$O$14<0,FALSE)),3,IF(OR(IFERROR(AND(DATOS!$M$14>=0,DATOS!$M$14<=30),FALSE),IFERROR(AND(DATOS!$O$14>=0,DATOS!$O$14<=30),FALSE)),4,IF(IFERROR(AND(DATOS!$Q$14>=0,DATOS!$Q$14<=10000),FALSE),5,6))))) -> 6 | B37: =DATOS!R14 -> OPERATIVA | C37: =DATOS!A14 -> TRACTOR | D37: =DATOS!H14 -> JYJT-42 | E37: =DATOS!E14 -> Same | F37: =DATOS!F14 -> FRUTTETO3 75 | G37: =DATOS!G14 -> 2017 | H37: =DATOS!C14 -> T7 | I37: =DATOS!B14 -> Rulo | J37: =DATOS!K14 -> 0 | K37: =DATOS!M14 -> 85 | L37: =DATOS!O14 -> 85 | M37: =DATOS!Q14 -> - | N37: =DATOS!S14 -> 82748.9 | O37: =DATOS!T14 -> 37800 | P37: =DATOS!U14 -> 120548.9 | Q37: =DATOS!V14 -> 76.378952 | R37: =DATOS!D14 -> T7 | S37: =DATOS!B14 -> Rulo
A38: =IF(DATOS!$R$18="FUERA DE SERVICIO",1,IF(DATOS!$R$18="EN MANTENCIÓN",2,IF(OR(IFERROR(DATOS!$M$18<0,FALSE),IFERROR(DATOS!$O$18<0,FALSE)),3,IF(OR(IFERROR(AND(DATOS!$M$18>=0,DATOS!$M$18<=30),FALSE),IFERROR(AND(DATOS!$O$18>=0,DATOS!$O$18<=30),FALSE)),4,IF(IFERROR(AND(DATOS!$Q$18>=0,DATOS!$Q$18<=10000),FALSE),5,6))))) -> 6 | B38: =DATOS!R18 -> OPERATIVA | C38: =DATOS!A18 -> TRACTOR | D38: =DATOS!H18 -> LWTR75 | E38: =DATOS!E18 -> Kubota | F38: =DATOS!F18 -> M8540DTN | G38: =DATOS!G18 -> 2020 | H38: =DATOS!C18 -> T10 | I38: =DATOS!B18 -> Paine | J38: =DATOS!K18 -> 0 | K38: =DATOS!M18 -> 786 | L38: =DATOS!O18 -> 786 | M38: =DATOS!Q18 -> - | N38: =DATOS!S18 -> 73128.89 | O38: =DATOS!T18 -> 37800 | P38: =DATOS!U18 -> 110928.89 | Q38: =DATOS!V18 -> 156.77887 | R38: =DATOS!D18 -> T10 | S38: =DATOS!B18 -> Paine
A39: =IF(DATOS!$R$11="FUERA DE SERVICIO",1,IF(DATOS!$R$11="EN MANTENCIÓN",2,IF(OR(IFERROR(DATOS!$M$11<0,FALSE),IFERROR(DATOS!$O$11<0,FALSE)),3,IF(OR(IFERROR(AND(DATOS!$M$11>=0,DATOS!$M$11<=30),FALSE),IFERROR(AND(DATOS!$O$11>=0,DATOS!$O$11<=30),FALSE)),4,IF(IFERROR(AND(DATOS!$Q$11>=0,DATOS!$Q$11<=10000),FALSE),5,6))))) -> 6 | B39: =DATOS!R11 -> OPERATIVA | C39: =DATOS!A11 -> TRACTOR | D39: =DATOS!H11 -> RDPG84 | E39: =DATOS!E11 -> John Deere | F39: =DATOS!F11 -> 5085GL | G39: =DATOS!G11 -> 2023 | H39: =DATOS!C11 -> T13 | I39: =DATOS!B11 -> Paine | J39: =DATOS!K11 -> 0 | K39: =DATOS!M11 -> 177 | L39: =DATOS!O11 -> 177 | M39: =DATOS!Q11 -> - | N39: =DATOS!S11 -> 148685.8 | O39: =DATOS!T11 -> 37800 | P39: =DATOS!U11 -> 186485.8 | Q39: =DATOS!V11 -> 142.91852 | R39: =DATOS!D11 -> T13 | S39: =DATOS!B11 -> Paine
A40: =IF(DATOS!$R$9="FUERA DE SERVICIO",1,IF(DATOS!$R$9="EN MANTENCIÓN",2,IF(OR(IFERROR(DATOS!$M$9<0,FALSE),IFERROR(DATOS!$O$9<0,FALSE)),3,IF(OR(IFERROR(AND(DATOS!$M$9>=0,DATOS!$M$9<=30),FALSE),IFERROR(AND(DATOS!$O$9>=0,DATOS!$O$9<=30),FALSE)),4,IF(IFERROR(AND(DATOS!$Q$9>=0,DATOS!$Q$9<=10000),FALSE),5,6))))) -> 5 | B40: =DATOS!R9 -> OPERATIVA | C40: =DATOS!A9 -> Vehiculo | D40: =DATOS!H9 -> TTWS70 | E40: =DATOS!E9 -> Maxus | F40: =DATOS!F9 -> T6 DCAB 4X2 2.0 | G40: =DATOS!G9 -> 2024 | H40: =DATOS!C9 -> CAMPO RULO | I40: =DATOS!B9 -> Rulo | J40: =DATOS!K9 -> 32559 | K40: =DATOS!M9 -> 208 | L40: =DATOS!O9 -> 208 | M40: =DATOS!Q9 -> 7441 | N40: =DATOS!S9 -> 214525.29 | O40: =DATOS!T9 -> 120599 | P40: =DATOS!U9 -> 335124.29 | Q40: =DATOS!V9 -> 178.01992 | R40: =DATOS!D9 -> CMTA10 | S40: =DATOS!B9 -> Rulo
A41: =IF(DATOS!$R$5="FUERA DE SERVICIO",1,IF(DATOS!$R$5="EN MANTENCIÓN",2,IF(OR(IFERROR(DATOS!$M$5<0,FALSE),IFERROR(DATOS!$O$5<0,FALSE)),3,IF(OR(IFERROR(AND(DATOS!$M$5>=0,DATOS!$M$5<=30),FALSE),IFERROR(AND(DATOS!$O$5>=0,DATOS!$O$5<=30),FALSE)),4,IF(IFERROR(AND(DATOS!$Q$5>=0,DATOS!$Q$5<=10000),FALSE),5,6))))) -> 6 | B41: =DATOS!R5 -> OPERATIVA | C41: =DATOS!A5 -> Vehiculo | D41: =DATOS!H5 -> TTWS71 | E41: =DATOS!E5 -> Maxus | F41: =DATOS!F5 -> T6 DCAB 4X2 2.0 | G41: =DATOS!G5 -> 2024 | H41: =DATOS!C5 -> CAMPO CERRILLOS | I41: =DATOS!B5 -> Cerrillos | J41: =DATOS!K5 -> 13750 | K41: =DATOS!M5 -> 267 | L41: =DATOS!O5 -> 267 | M41: =DATOS!Q5 -> 11250 | N41: =DATOS!S5 -> 319480.68 | O41: =DATOS!T5 -> 155599 | P41: =DATOS!U5 -> 475079.68 | Q41: =DATOS!V5 -> 262.92236 | R41: =DATOS!D5 -> CMTA11 | S41: =DATOS!B5 -> Cerrillos
A42: =IF(DATOS!$R$12="FUERA DE SERVICIO",1,IF(DATOS!$R$12="EN MANTENCIÓN",2,IF(OR(IFERROR(DATOS!$M$12<0,FALSE),IFERROR(DATOS!$O$12<0,FALSE)),3,IF(OR(IFERROR(AND(DATOS!$M$12>=0,DATOS!$M$12<=30),FALSE),IFERROR(AND(DATOS!$O$12>=0,DATOS!$O$12<=30),FALSE)),4,IF(IFERROR(AND(DATOS!$Q$12>=0,DATOS!$Q$12<=10000),FALSE),5,6))))) -> 6 | B42: =DATOS!R12 -> OPERATIVA | C42: =DATOS!A12 -> TRACTOR | D42: =DATOS!H12 -> TZSG44 | E42: =DATOS!E12 -> Kubota | F42: =DATOS!F12 -> M8540 N | G42: =DATOS!G12 -> 2025 | H42: =DATOS!C12 -> T14 | I42: =DATOS!B12 -> Rulo | J42: =DATOS!K12 -> 0 | K42: =DATOS!M12 -> 908 | L42: =DATOS!O12 -> 908 | M42: =DATOS!Q12 -> - | N42: =DATOS!S12 -> 134734.18 | O42: =DATOS!T12 -> 37800 | P42: =DATOS!U12 -> 172534.18 | Q42: =DATOS!V12 -> 244.2789 | R42: =DATOS!D12 -> T14 | S42: =DATOS!B12 -> Rulo
A45: Nota: los KPI se calculan desde la hoja DATOS. Si cambias datos, usa F9 / Datos > Actualizar todo.

Sheet DATOS
A1: TIPO VEHICULO | B1: UBICACIÓN | C1: RESPONSABLE | D1: MAQUINARIA | E1: MARCA | F1: MODELO | G1: AÑO FABRICACIÓN | H1: PATENTE | I1: KM DE comienzo | J1: KM | K1: KM ACTUAL | L1: REVISION TECNICA | M1: ESTADO DE RT | N1: GASES Y CONTAMINANTES | O1: ESTADO GASES | P1: PROXIMO Cambio de aceite | Q1: CAMBIO DE ACEITE | R1: ESTADO | S1: GASTO EN COMBUSTIBLES | T1: $ EN MANTENCIÓN | U1: COSTO TOTAL | V1: COSTO X KM | W1: PRIORIDAD | X1: ALERTAS | Y1: Columna1
A2: Vehiculo | B2: Rulo | C2: =_xlfn.XLOOKUP(Tabla1[[#This Row],[MAQUINARIA]],Hoja3!A:A,Hoja3!C:C) -> RODRIGO SALINAS | D2: CMTA07 | E2: Nissan | F2: Navara DC SE 2,3D | G2: 2022 | H2: RHYH23 | I2: =SUMIF(GPS!$D2:$D$1048576,Tabla1[[#This Row],[MAQUINARIA]],GPS!$G$2:$G$1048576) -> 4742.93 | K2: =Tabla1[[#This Row],[KM]]+SUMIF(GPS!$D$746:$D$1048570,Tabla1[[#This Row],[MAQUINARIA]],GPS!$G$746:$G$1048570) -> 0 | L2: - | M2: =IF(L2="-","-",L2-TODAY()) -> - | N2: =Tabla1[[#This Row],[REVISION TECNICA]] -> - | O2: =IF(Tabla1[[#This Row],[GASES Y CONTAMINANTES]]="-","-",Tabla1[[#This Row],[GASES Y CONTAMINANTES]]-TODAY()) -> - | Q2: =IF(Tabla1[[#This Row],[PROXIMO Cambio de aceite]]="","-",Tabla1[[#This Row],[PROXIMO Cambio de aceite]]-Tabla1[[#This Row],[KM ACTUAL]]) -> - | R2: ARRIENDO | S2: =SUMIF(GPS!D:D,Tabla1[[#This Row],[MAQUINARIA]],GPS!M:M) -> 632917.66 | T2: =SUMIF('GASTOS Y MANTENCIONES'!B:B,C2,'GASTOS Y MANTENCIONES'!C:C) -> 37800 | U2: =Tabla1[[#This Row],[GASTO EN COMBUSTIBLES]]+Tabla1[[#This Row],[$ EN MANTENCIÓN]] -> 670717.66 | V2: =IFERROR((Tabla1[[#This Row],[GASTO EN COMBUSTIBLES]]+Tabla1[[#This Row],[$ EN MANTENCIÓN]])/Tabla1[[#This Row],[KM DE comienzo]],"-") -> 141.4142 | W2: =IF($R2="FUERA DE SERVICIO",1,IF($R2="EN MANTENCIÓN",2,IF(OR(AND(ISNUMBER($M2),$M2<0),AND(ISNUMBER($O2),$O2<0)),3,IF(OR(AND(ISNUMBER($M2),$M2<=30),AND(ISNUMBER($O2),$O2<=30)),4,IF(AND(ISNUMBER($Q2),$Q2<=10000),5,6))))) -> 6 | X2: =IF($R2="FUERA DE SERVICIO","Fuera de servicio",IF($R2="EN MANTENCIÓN","En mantención",IF(AND(ISNUMBER($M2),$M2<0),"RT vencida",IF(AND(ISNUMBER($O2),$O2<0),"Gases vencidos",IF(AND(ISNUMBER($M2),$M2<=30),"RT próxima",IF(AND(ISNUMBER($O2),$O2<=30),"Gases próximos",IF(AND(ISNUMBER($Q2),$Q2<=500),"Cambio aceite próximo","OK"))))))) -> OK | Y2: =Tabla1[[#This Row],[PRIORIDAD]]+(ROW()/1000) -> 6.002 | Z2: {=_xlfn.UNIQUE(Tabla1[ESTADO])} -> ARRIENDO
A3: Vehiculo | B3: Rulo | C3: =_xlfn.XLOOKUP(Tabla1[[#This Row],[MAQUINARIA]],Hoja3!A:A,Hoja3!C:C) -> VG PIÑALEO | D3: CMTA03 | E3: Volkswagen | F3: Saveiro | G3: 2018 | H3: KCTL49 | I3: =SUMIF(GPS!$D3:$D$1048576,Tabla1[[#This Row],[MAQUINARIA]],GPS!$G$2:$G$1048576) -> 1785.13 | J3: 111371 | K3: =Tabla1[[#This Row],[KM]]+SUMIF(GPS!$D$746:$D$1048570,Tabla1[[#This Row],[MAQUINARIA]],GPS!$G$746:$G$1048570) -> 111468.22 | L3: 46296 | M3: =IF(L3="-","-",L3-TODAY()) -> 85 | N3: 46266 | O3: =IF(Tabla1[[#This Row],[GASES Y CONTAMINANTES]]="-","-",Tabla1[[#This Row],[GASES Y CONTAMINANTES]]-TODAY()) -> 55 | P3: 110900 | Q3: =IF(Tabla1[[#This Row],[PROXIMO Cambio de aceite]]="","-",Tabla1[[#This Row],[PROXIMO Cambio de aceite]]-Tabla1[[#This Row],[KM ACTUAL]]) -> -568.22 | R3: OPERATIVA | S3: =SUMIF(GPS!D:D,Tabla1[[#This Row],[MAQUINARIA]],GPS!M:M) -> 371846.41 | T3: =SUMIF('GASTOS Y MANTENCIONES'!B:B,C3,'GASTOS Y MANTENCIONES'!C:C) -> 70800 | U3: =Tabla1[[#This Row],[GASTO EN COMBUSTIBLES]]+Tabla1[[#This Row],[$ EN MANTENCIÓN]] -> 442646.41 | V3: =IFERROR((Tabla1[[#This Row],[GASTO EN COMBUSTIBLES]]+Tabla1[[#This Row],[$ EN MANTENCIÓN]])/Tabla1[[#This Row],[KM DE comienzo]],"-") -> 247.96312 | W3: =IF($R3="FUERA DE SERVICIO",1,IF($R3="EN MANTENCIÓN",2,IF(OR(AND(ISNUMBER($M3),$M3<0),AND(ISNUMBER($O3),$O3<0)),3,IF(OR(AND(ISNUMBER($M3),$M3<=30),AND(ISNUMBER($O3),$O3<=30)),4,IF(AND(ISNUMBER($Q3),$Q3<=10000),5,6))))) -> 5 | X3: =IF($R3="FUERA DE SERVICIO","Fuera de servicio",IF($R3="EN MANTENCIÓN","En mantención",IF(AND(ISNUMBER($M3),$M3<0),"RT vencida",IF(AND(ISNUMBER($O3),$O3<0),"Gases vencidos",IF(AND(ISNUMBER($M3),$M3<=30),"RT próxima",IF(AND(ISNUMBER($O3),$O3<=30),"Gases próximos",IF(AND(ISNUMBER($Q3),$Q3<=500),"Cambio aceite próximo","OK"))))))) -> Cambio aceite próximo | Y3: =Tabla1[[#This Row],[PRIORIDAD]]+(ROW()/1000) -> 5.003 | Z3: OPERATIVA
A4: Vehiculo | B4: Rulo | C4: =_xlfn.XLOOKUP(Tabla1[[#This Row],[MAQUINARIA]],Hoja3!A:A,Hoja3!C:C) -> VG GERARDO | D4: CMTA04 | E4: Volkswagen | F4: Saveiro | G4: 2018 | H4: KCTL47 | I4: =SUMIF(GPS!$D4:$D$1048576,Tabla1[[#This Row],[MAQUINARIA]],GPS!$G$2:$G$1048576) -> 1986.97 | J4: 113508 | K4: =Tabla1[[#This Row],[KM]]+SUMIF(GPS!$D$746:$D$1048570,Tabla1[[#This Row],[MAQUINARIA]],GPS!$G$746:$G$1048570) -> 113508.42 | L4: 46388 | M4: =IF(L4="-","-",L4-TODAY()) -> 177 | N4: 46388 | O4: =IF(Tabla1[[#This Row],[GASES Y CONTAMINANTES]]="-","-",Tabla1[[#This Row],[GASES Y CONTAMINANTES]]-TODAY()) -> 177 | P4: 117748 | Q4: =IF(Tabla1[[#This Row],[PROXIMO Cambio de aceite]]="","-",Tabla1[[#This Row],[PROXIMO Cambio de aceite]]-Tabla1[[#This Row],[KM ACTUAL]]) -> 4239.58 | R4: OPERATIVA | S4: =SUMIF(GPS!D:D,Tabla1[[#This Row],[MAQUINARIA]],GPS!M:M) -> 341364.95 | T4: =SUMIF('GASTOS Y MANTENCIONES'!B:B,C4,'GASTOS Y MANTENCIONES'!C:C) -> 135674 | U4: =Tabla1[[#This Row],[GASTO EN COMBUSTIBLES]]+Tabla1[[#This Row],[$ EN MANTENCIÓN]] -> 477038.95 | V4: =IFERROR((Tabla1[[#This Row],[GASTO EN COMBUSTIBLES]]+Tabla1[[#This Row],[$ EN MANTENCIÓN]])/Tabla1[[#This Row],[KM DE comienzo]],"-") -> 240.08362 | W4: =IF($R4="FUERA DE SERVICIO",1,IF($R4="EN MANTENCIÓN",2,IF(OR(AND(ISNUMBER($M4),$M4<0),AND(ISNUMBER($O4),$O4<0)),3,IF(OR(AND(ISNUMBER($M4),$M4<=30),AND(ISNUMBER($O4),$O4<=30)),4,IF(AND(ISNUMBER($Q4),$Q4<=10000),5,6))))) -> 5 | X4: =IF($R4="FUERA DE SERVICIO","Fuera de servicio",IF($R4="EN MANTENCIÓN","En mantención",IF(AND(ISNUMBER($M4),$M4<0),"RT vencida",IF(AND(ISNUMBER($O4),$O4<0),"Gases vencidos",IF(AND(ISNUMBER($M4),$M4<=30),"RT próxima",IF(AND(ISNUMBER($O4),$O4<=30),"Gases próximos",IF(AND(ISNUMBER($Q4),$Q4<=500),"Cambio aceite próximo","OK"))))))) -> OK | Y4: =Tabla1[[#This Row],[PRIORIDAD]]+(ROW()/1000) -> 5.004 | Z4: EN MANTENCIÓN
A5: Vehiculo | B5: Cerrillos | C5: =_xlfn.XLOOKUP(Tabla1[[#This Row],[MAQUINARIA]],Hoja3!A:A,Hoja3!C:C) -> CAMPO CERRILLOS | D5: CMTA11 | E5: Maxus | F5: T6 DCAB 4X2 2.0 | G5: 2024 | H5: TTWS71 | I5: =SUMIF(GPS!$D5:$D$1048576,Tabla1[[#This Row],[MAQUINARIA]],GPS!$G$2:$G$1048576) -> 1806.92 | J5: 13750 | K5: =Tabla1[[#This Row],[KM]]+SUMIF(GPS!$D$746:$D$1048570,Tabla1[[#This Row],[MAQUINARIA]],GPS!$G$746:$G$1048570) -> 13750 | L5: 46478 | M5: =IF(L5="-","-",L5-TODAY()) -> 267 | N5: =Tabla1[[#This Row],[REVISION TECNICA]] -> 46478 | O5: =IF(Tabla1[[#This Row],[GASES Y CONTAMINANTES]]="-","-",Tabla1[[#This Row],[GASES Y CONTAMINANTES]]-TODAY()) -> 267 | P5: 25000 | Q5: =IF(Tabla1[[#This Row],[PROXIMO Cambio de aceite]]="","-",Tabla1[[#This Row],[PROXIMO Cambio de aceite]]-Tabla1[[#This Row],[KM ACTUAL]]) -> 11250 | R5: OPERATIVA | S5: =SUMIF(GPS!D:D,Tabla1[[#This Row],[MAQUINARIA]],GPS!M:M) -> 319480.68 | T5: =SUMIF('GASTOS Y MANTENCIONES'!B:B,C5,'GASTOS Y MANTENCIONES'!C:C) -> 155599 | U5: =Tabla1[[#This Row],[GASTO EN COMBUSTIBLES]]+Tabla1[[#This Row],[$ EN MANTENCIÓN]] -> 475079.68 | V5: =IFERROR((Tabla1[[#This Row],[GASTO EN COMBUSTIBLES]]+Tabla1[[#This Row],[$ EN MANTENCIÓN]])/Tabla1[[#This Row],[KM DE comienzo]],"-") -> 262.92236 | W5: =IF($R5="FUERA DE SERVICIO",1,IF($R5="EN MANTENCIÓN",2,IF(OR(AND(ISNUMBER($M5),$M5<0),AND(ISNUMBER($O5),$O5<0)),3,IF(OR(AND(ISNUMBER($M5),$M5<=30),AND(ISNUMBER($O5),$O5<=30)),4,IF(AND(ISNUMBER($Q5),$Q5<=10000),5,6))))) -> 6 | X5: =IF($R5="FUERA DE SERVICIO","Fuera de servicio",IF($R5="EN MANTENCIÓN","En mantención",IF(AND(ISNUMBER($M5),$M5<0),"RT vencida",IF(AND(ISNUMBER($O5),$O5<0),"Gases vencidos",IF(AND(ISNUMBER($M5),$M5<=30),"RT próxima",IF(AND(ISNUMBER($O5),$O5<=30),"Gases próximos",IF(AND(ISNUMBER($Q5),$Q5<=500),"Cambio aceite próximo","OK"))))))) -> OK | Y5: =Tabla1[[#This Row],[PRIORIDAD]]+(ROW()/1000) -> 6.005 | Z5: FUERA DE SERVICIO
A6: Vehiculo | B6: Paine | C6: =_xlfn.XLOOKUP(Tabla1[[#This Row],[MAQUINARIA]],Hoja3!A:A,Hoja3!C:C) -> GONZALO GUERRERO | D6: CMTA08 | E6: Nissan | F6: Navara DC SE 2,3D | G6: 2022 | H6: RHYH16 | I6: =SUMIF(GPS!$D6:$D$1048576,Tabla1[[#This Row],[MAQUINARIA]],GPS!$G$2:$G$1048576) -> 2011.13 | K6: =Tabla1[[#This Row],[KM]]+SUMIF(GPS!$D$746:$D$1048570,Tabla1[[#This Row],[MAQUINARIA]],GPS!$G$746:$G$1048570) -> 0 | L6: - | M6: =IF(L6="-","-",L6-TODAY()) -> - | N6: =Tabla1[[#This Row],[REVISION TECNICA]] -> - | O6: =IF(Tabla1[[#This Row],[GASES Y CONTAMINANTES]]="-","-",Tabla1[[#This Row],[GASES Y CONTAMINANTES]]-TODAY()) -> - | Q6: =IF(Tabla1[[#This Row],[PROXIMO Cambio de aceite]]="","-",Tabla1[[#This Row],[PROXIMO Cambio de aceite]]-Tabla1[[#This Row],[KM ACTUAL]]) -> - | R6: ARRIENDO | S6: =SUMIF(GPS!D:D,Tabla1[[#This Row],[MAQUINARIA]],GPS!M:M) -> 264639.02 | T6: =SUMIF('GASTOS Y MANTENCIONES'!B:B,C6,'GASTOS Y MANTENCIONES'!C:C) -> 37800 | U6: =Tabla1[[#This Row],[GASTO EN COMBUSTIBLES]]+Tabla1[[#This Row],[$ EN MANTENCIÓN]] -> 302439.02 | V6: =IFERROR((Tabla1[[#This Row],[GASTO EN COMBUSTIBLES]]+Tabla1[[#This Row],[$ EN MANTENCIÓN]])/Tabla1[[#This Row],[KM DE comienzo]],"-") -> 150.38263 | W6: =IF($R6="FUERA DE SERVICIO",1,IF($R6="EN MANTENCIÓN",2,IF(OR(AND(ISNUMBER($M6),$M6<0),AND(ISNUMBER($O6),$O6<0)),3,IF(OR(AND(ISNUMBER($M6),$M6<=30),AND(ISNUMBER($O6),$O6<=30)),4,IF(AND(ISNUMBER($Q6),$Q6<=10000),5,6))))) -> 6 | X6: =IF($R6="FUERA DE SERVICIO","Fuera de servicio",IF($R6="EN MANTENCIÓN","En mantención",IF(AND(ISNUMBER($M6),$M6<0),"RT vencida",IF(AND(ISNUMBER($O6),$O6<0),"Gases vencidos",IF(AND(ISNUMBER($M6),$M6<=30),"RT próxima",IF(AND(ISNUMBER($O6),$O6<=30),"Gases próximos",IF(AND(ISNUMBER($Q6),$Q6<=500),"Cambio aceite próximo","OK"))))))) -> OK | Y6: =Tabla1[[#This Row],[PRIORIDAD]]+(ROW()/1000) -> 6.006
A7: Vehiculo | B7: Cerrillos | C7: =_xlfn.XLOOKUP(Tabla1[[#This Row],[MAQUINARIA]],Hoja3!A:A,Hoja3!C:C) -> SERGIO ROJAS | D7: CMTA02 | E7: Nissan | F7: NP300 | G7: 2018 | H7: KBVX10 | I7: =SUMIF(GPS!$D7:$D$1048576,Tabla1[[#This Row],[MAQUINARIA]],GPS!$G$2:$G$1048576) -> 1103.53 | J7: 172200 | K7: =Tabla1[[#This Row],[KM]]+SUMIF(GPS!$D$746:$D$1048570,Tabla1[[#This Row],[MAQUINARIA]],GPS!$G$746:$G$1048570) -> 172278.82 | L7: 46419 | M7: =IF(L7="-","-",L7-TODAY()) -> 208 | N7: =Tabla1[[#This Row],[REVISION TECNICA]] -> 46419 | O7: =IF(Tabla1[[#This Row],[GASES Y CONTAMINANTES]]="-","-",Tabla1[[#This Row],[GASES Y CONTAMINANTES]]-TODAY()) -> 208 | P7: 180219 | Q7: =IF(Tabla1[[#This Row],[PROXIMO Cambio de aceite]]="","-",Tabla1[[#This Row],[PROXIMO Cambio de aceite]]-Tabla1[[#This Row],[KM ACTUAL]]) -> 7940.18 | R7: OPERATIVA | S7: =SUMIF(GPS!D:D,Tabla1[[#This Row],[MAQUINARIA]],GPS!M:M) -> 255877.05 | T7: =SUMIF('GASTOS Y MANTENCIONES'!B:B,C7,'GASTOS Y MANTENCIONES'!C:C) -> 270796 | U7: =Tabla1[[#This Row],[GASTO EN COMBUSTIBLES]]+Tabla1[[#This Row],[$ EN MANTENCIÓN]] -> 526673.05 | V7: =IFERROR((Tabla1[[#This Row],[GASTO EN COMBUSTIBLES]]+Tabla1[[#This Row],[$ EN MANTENCIÓN]])/Tabla1[[#This Row],[KM DE comienzo]],"-") -> 477.26211 | W7: =IF($R7="FUERA DE SERVICIO",1,IF($R7="EN MANTENCIÓN",2,IF(OR(AND(ISNUMBER($M7),$M7<0),AND(ISNUMBER($O7),$O7<0)),3,IF(OR(AND(ISNUMBER($M7),$M7<=30),AND(ISNUMBER($O7),$O7<=30)),4,IF(AND(ISNUMBER($Q7),$Q7<=10000),5,6))))) -> 5 | X7: =IF($R7="FUERA DE SERVICIO","Fuera de servicio",IF($R7="EN MANTENCIÓN","En mantención",IF(AND(ISNUMBER($M7),$M7<0),"RT vencida",IF(AND(ISNUMBER($O7),$O7<0),"Gases vencidos",IF(AND(ISNUMBER($M7),$M7<=30),"RT próxima",IF(AND(ISNUMBER($O7),$O7<=30),"Gases próximos",IF(AND(ISNUMBER($Q7),$Q7<=500),"Cambio aceite próximo","OK"))))))) -> OK | Y7: =Tabla1[[#This Row],[PRIORIDAD]]+(ROW()/1000) -> 5.007
A8: Vehiculo | B8: Paine | C8: =_xlfn.XLOOKUP(Tabla1[[#This Row],[MAQUINARIA]],Hoja3!A:A,Hoja3!C:C) -> CAMPO PAINE | D8: CMTA01 | E8: Mitsubishi | F8: L200 Katana | G8: 2015 | H8: GRTF64 | I8: =SUMIF(GPS!$D8:$D$1048576,Tabla1[[#This Row],[MAQUINARIA]],GPS!$G$2:$G$1048576) -> 2243.2 | J8: 199236 | K8: =Tabla1[[#This Row],[KM]]+SUMIF(GPS!$D$746:$D$1048570,Tabla1[[#This Row],[MAQUINARIA]],GPS!$G$746:$G$1048570) -> 199236 | L8: 46204 | M8: =IF(L8="-","-",L8-TODAY()) -> -7 | N8: =Tabla1[[#This Row],[REVISION TECNICA]] -> 46204 | O8: =IF(Tabla1[[#This Row],[GASES Y CONTAMINANTES]]="-","-",Tabla1[[#This Row],[GASES Y CONTAMINANTES]]-TODAY()) -> -7 | P8: 206000 | Q8: =IF(Tabla1[[#This Row],[PROXIMO Cambio de aceite]]="","-",Tabla1[[#This Row],[PROXIMO Cambio de aceite]]-Tabla1[[#This Row],[KM ACTUAL]]) -> 6764 | R8: OPERATIVA | S8: =SUMIF(GPS!D:D,Tabla1[[#This Row],[MAQUINARIA]],GPS!M:M) -> 220296.76 | T8: =SUMIF('GASTOS Y MANTENCIONES'!B:B,C8,'GASTOS Y MANTENCIONES'!C:C) -> 107800 | U8: =Tabla1[[#This Row],[GASTO EN COMBUSTIBLES]]+Tabla1[[#This Row],[$ EN MANTENCIÓN]] -> 328096.76 | V8: =IFERROR((Tabla1[[#This Row],[GASTO EN COMBUSTIBLES]]+Tabla1[[#This Row],[$ EN MANTENCIÓN]])/Tabla1[[#This Row],[KM DE comienzo]],"-") -> 146.26282 | W8: =IF($R8="FUERA DE SERVICIO",1,IF($R8="EN MANTENCIÓN",2,IF(OR(AND(ISNUMBER($M8),$M8<0),AND(ISNUMBER($O8),$O8<0)),3,IF(OR(AND(ISNUMBER($M8),$M8<=30),AND(ISNUMBER($O8),$O8<=30)),4,IF(AND(ISNUMBER($Q8),$Q8<=10000),5,6))))) -> 3 | X8: =IF($R8="FUERA DE SERVICIO","Fuera de servicio",IF($R8="EN MANTENCIÓN","En mantención",IF(AND(ISNUMBER($M8),$M8<0),"RT vencida",IF(AND(ISNUMBER($O8),$O8<0),"Gases vencidos",IF(AND(ISNUMBER($M8),$M8<=30),"RT próxima",IF(AND(ISNUMBER($O8),$O8<=30),"Gases próximos",IF(AND(ISNUMBER($Q8),$Q8<=500),"Cambio aceite próximo","OK"))))))) -> RT vencida | Y8: =Tabla1[[#This Row],[PRIORIDAD]]+(ROW()/1000) -> 3.008
A9: Vehiculo | B9: Rulo | C9: =_xlfn.XLOOKUP(Tabla1[[#This Row],[MAQUINARIA]],Hoja3!A:A,Hoja3!C:C) -> CAMPO RULO | D9: CMTA10 | E9: Maxus | F9: T6 DCAB 4X2 2.0 | G9: 2024 | H9: TTWS70 | I9: =SUMIF(GPS!$D9:$D$1048576,Tabla1[[#This Row],[MAQUINARIA]],GPS!$G$2:$G$1048576) -> 1882.51 | J9: 32559 | K9: =Tabla1[[#This Row],[KM]]+SUMIF(GPS!$D$746:$D$1048570,Tabla1[[#This Row],[MAQUINARIA]],GPS!$G$746:$G$1048570) -> 32559 | L9: 46419 | M9: =IF(L9="-","-",L9-TODAY()) -> 208 | N9: =Tabla1[[#This Row],[REVISION TECNICA]] -> 46419 | O9: =IF(Tabla1[[#This Row],[GASES Y CONTAMINANTES]]="-","-",Tabla1[[#This Row],[GASES Y CONTAMINANTES]]-TODAY()) -> 208 | P9: 40000 | Q9: =IF(Tabla1[[#This Row],[PROXIMO Cambio de aceite]]="","-",Tabla1[[#This Row],[PROXIMO Cambio de aceite]]-Tabla1[[#This Row],[KM ACTUAL]]) -> 7441 | R9: OPERATIVA | S9: =SUMIF(GPS!D:D,Tabla1[[#This Row],[MAQUINARIA]],GPS!M:M) -> 214525.29 | T9: =SUMIF('GASTOS Y MANTENCIONES'!B:B,C9,'GASTOS Y MANTENCIONES'!C:C) -> 120599 | U9: =Tabla1[[#This Row],[GASTO EN COMBUSTIBLES]]+Tabla1[[#This Row],[$ EN MANTENCIÓN]] -> 335124.29 | V9: =IFERROR((Tabla1[[#This Row],[GASTO EN COMBUSTIBLES]]+Tabla1[[#This Row],[$ EN MANTENCIÓN]])/Tabla1[[#This Row],[KM DE comienzo]],"-") -> 178.01992 | W9: =IF($R9="FUERA DE SERVICIO",1,IF($R9="EN MANTENCIÓN",2,IF(OR(AND(ISNUMBER($M9),$M9<0),AND(ISNUMBER($O9),$O9<0)),3,IF(OR(AND(ISNUMBER($M9),$M9<=30),AND(ISNUMBER($O9),$O9<=30)),4,IF(AND(ISNUMBER($Q9),$Q9<=10000),5,6))))) -> 5 | X9: =IF($R9="FUERA DE SERVICIO","Fuera de servicio",IF($R9="EN MANTENCIÓN","En mantención",IF(AND(ISNUMBER($M9),$M9<0),"RT vencida",IF(AND(ISNUMBER($O9),$O9<0),"Gases vencidos",IF(AND(ISNUMBER($M9),$M9<=30),"RT próxima",IF(AND(ISNUMBER($O9),$O9<=30),"Gases próximos",IF(AND(ISNUMBER($Q9),$Q9<=500),"Cambio aceite próximo","OK"))))))) -> OK | Y9: =Tabla1[[#This Row],[PRIORIDAD]]+(ROW()/1000) -> 5.009
A10: Vehiculo | B10: Cerrillos | C10: =_xlfn.XLOOKUP(Tabla1[[#This Row],[MAQUINARIA]],Hoja3!A:A,Hoja3!C:C) -> VG CERRILLOS | D10: CMTA05 | E10: Volkswagen | F10: Saveiro | G10: 2018 | H10: KCTL48 | I10: =SUMIF(GPS!$D10:$D$1048576,Tabla1[[#This Row],[MAQUINARIA]],GPS!$G$2:$G$1048576) -> 1407.99 | J10: 106659 | K10: =Tabla1[[#This Row],[KM]]+SUMIF(GPS!$D$746:$D$1048570,Tabla1[[#This Row],[MAQUINARIA]],GPS!$G$746:$G$1048570) -> 106758.78 | L10: 46327 | M10: =IF(L10="-","-",L10-TODAY()) -> 116 | N10: 46327 | O10: =IF(Tabla1[[#This Row],[GASES Y CONTAMINANTES]]="-","-",Tabla1[[#This Row],[GASES Y CONTAMINANTES]]-TODAY()) -> 116 | P10: 108000 | Q10: =IF(Tabla1[[#This Row],[PROXIMO Cambio de aceite]]="","-",Tabla1[[#This Row],[PROXIMO Cambio de aceite]]-Tabla1[[#This Row],[KM ACTUAL]]) -> 1241.22 | R10: OPERATIVA | S10: =SUMIF(GPS!D:D,Tabla1[[#This Row],[MAQUINARIA]],GPS!M:M) -> 206031.64 | T10: =SUMIF('GASTOS Y MANTENCIONES'!B:B,C10,'GASTOS Y MANTENCIONES'!C:C) -> 70800 | U10: =Tabla1[[#This Row],[GASTO EN COMBUSTIBLES]]+Tabla1[[#This Row],[$ EN MANTENCIÓN]] -> 276831.64 | V10: =IFERROR((Tabla1[[#This Row],[GASTO EN COMBUSTIBLES]]+Tabla1[[#This Row],[$ EN MANTENCIÓN]])/Tabla1[[#This Row],[KM DE comienzo]],"-") -> 196.61477 | W10: =IF($R10="FUERA DE SERVICIO",1,IF($R10="EN MANTENCIÓN",2,IF(OR(AND(ISNUMBER($M10),$M10<0),AND(ISNUMBER($O10),$O10<0)),3,IF(OR(AND(ISNUMBER($M10),$M10<=30),AND(ISNUMBER($O10),$O10<=30)),4,IF(AND(ISNUMBER($Q10),$Q10<=10000),5,6))))) -> 5 | X10: =IF($R10="FUERA DE SERVICIO","Fuera de servicio",IF($R10="EN MANTENCIÓN","En mantención",IF(AND(ISNUMBER($M10),$M10<0),"RT vencida",IF(AND(ISNUMBER($O10),$O10<0),"Gases vencidos",IF(AND(ISNUMBER($M10),$M10<=30),"RT próxima",IF(AND(ISNUMBER($O10),$O10<=30),"Gases próximos",IF(AND(ISNUMBER($Q10),$Q10<=500),"Cambio aceite próximo","OK"))))))) -> OK | Y10: =Tabla1[[#This Row],[PRIORIDAD]]+(ROW()/1000) -> 5.01
A11: TRACTOR | B11: Paine | C11: =_xlfn.XLOOKUP(Tabla1[[#This Row],[MAQUINARIA]],Hoja3!A:A,Hoja3!C:C) -> T13 | D11: T13 | E11: John Deere | F11: 5085GL | G11: 2023 | H11: RDPG84 | I11: =SUMIF(GPS!$D11:$D$1048576,Tabla1[[#This Row],[MAQUINARIA]],GPS!$G$2:$G$1048576) -> 1304.84 | K11: =Tabla1[[#This Row],[KM]]+SUMIF(GPS!$D$746:$D$1048570,Tabla1[[#This Row],[MAQUINARIA]],GPS!$G$746:$G$1048570) -> 0 | L11: 46388 | M11: =IF(L11="-","-",L11-TODAY()) -> 177 | N11: =Tabla1[[#This Row],[REVISION TECNICA]] -> 46388 | O11: =IF(Tabla1[[#This Row],[GASES Y CONTAMINANTES]]="-","-",Tabla1[[#This Row],[GASES Y CONTAMINANTES]]-TODAY()) -> 177 | Q11: =IF(Tabla1[[#This Row],[PROXIMO Cambio de aceite]]="","-",Tabla1[[#This Row],[PROXIMO Cambio de aceite]]-Tabla1[[#This Row],[KM ACTUAL]]) -> - | R11: OPERATIVA | S11: =SUMIF(GPS!D:D,Tabla1[[#This Row],[MAQUINARIA]],GPS!M:M) -> 148685.8 | T11: =SUMIF('GASTOS Y MANTENCIONES'!B:B,C11,'GASTOS Y MANTENCIONES'!C:C) -> 37800 | U11: =Tabla1[[#This Row],[GASTO EN COMBUSTIBLES]]+Tabla1[[#This Row],[$ EN MANTENCIÓN]] -> 186485.8 | V11: =IFERROR((Tabla1[[#This Row],[GASTO EN COMBUSTIBLES]]+Tabla1[[#This Row],[$ EN MANTENCIÓN]])/Tabla1[[#This Row],[KM DE comienzo]],"-") -> 142.91852 | W11: =IF($R11="FUERA DE SERVICIO",1,IF($R11="EN MANTENCIÓN",2,IF(OR(AND(ISNUMBER($M11),$M11<0),AND(ISNUMBER($O11),$O11<0)),3,IF(OR(AND(ISNUMBER($M11),$M11<=30),AND(ISNUMBER($O11),$O11<=30)),4,IF(AND(ISNUMBER($Q11),$Q11<=10000),5,6))))) -> 6 | X11: =IF($R11="FUERA DE SERVICIO","Fuera de servicio",IF($R11="EN MANTENCIÓN","En mantención",IF(AND(ISNUMBER($M11),$M11<0),"RT vencida",IF(AND(ISNUMBER($O11),$O11<0),"Gases vencidos",IF(AND(ISNUMBER($M11),$M11<=30),"RT próxima",IF(AND(ISNUMBER($O11),$O11<=30),"Gases próximos",IF(AND(ISNUMBER($Q11),$Q11<=500),"Cambio aceite próximo","OK"))))))) -> OK | Y11: =Tabla1[[#This Row],[PRIORIDAD]]+(ROW()/1000) -> 6.011
A12: TRACTOR | B12: Rulo | C12: =_xlfn.XLOOKUP(Tabla1[[#This Row],[MAQUINARIA]],Hoja3!A:A,Hoja3!C:C) -> T14 | D12: T14 | E12: Kubota | F12: M8540 N | G12: 2025 | H12: TZSG44 | I12: =SUMIF(GPS!$D12:$D$1048576,Tabla1[[#This Row],[MAQUINARIA]],GPS!$G$2:$G$1048576) -> 706.3 | K12: =Tabla1[[#This Row],[KM]]+SUMIF(GPS!$D$746:$D$1048570,Tabla1[[#This Row],[MAQUINARIA]],GPS!$G$746:$G$1048570) -> 0 | L12: 47119 | M12: =IF(L12="-","-",L12-TODAY()) -> 908 | N12: =Tabla1[[#This Row],[REVISION TECNICA]] -> 47119 | O12: =IF(Tabla1[[#This Row],[GASES Y CONTAMINANTES]]="-","-",Tabla1[[#This Row],[GASES Y CONTAMINANTES]]-TODAY()) -> 908 | Q12: =IF(Tabla1[[#This Row],[PROXIMO Cambio de aceite]]="","-",Tabla1[[#This Row],[PROXIMO Cambio de aceite]]-Tabla1[[#This Row],[KM ACTUAL]]) -> - | R12: OPERATIVA | S12: =SUMIF(GPS!D:D,Tabla1[[#This Row],[MAQUINARIA]],GPS!M:M) -> 134734.18 | T12: =SUMIF('GASTOS Y MANTENCIONES'!B:B,C12,'GASTOS Y MANTENCIONES'!C:C) -> 37800 | U12: =Tabla1[[#This Row],[GASTO EN COMBUSTIBLES]]+Tabla1[[#This Row],[$ EN MANTENCIÓN]] -> 172534.18 | V12: =IFERROR((Tabla1[[#This Row],[GASTO EN COMBUSTIBLES]]+Tabla1[[#This Row],[$ EN MANTENCIÓN]])/Tabla1[[#This Row],[KM DE comienzo]],"-") -> 244.2789 | W12: =IF($R12="FUERA DE SERVICIO",1,IF($R12="EN MANTENCIÓN",2,IF(OR(AND(ISNUMBER($M12),$M12<0),AND(ISNUMBER($O12),$O12<0)),3,IF(OR(AND(ISNUMBER($M12),$M12<=30),AND(ISNUMBER($O12),$O12<=30)),4,IF(AND(ISNUMBER($Q12),$Q12<=10000),5,6))))) -> 6 | X12: =IF($R12="FUERA DE SERVICIO","Fuera de servicio",IF($R12="EN MANTENCIÓN","En mantención",IF(AND(ISNUMBER($M12),$M12<0),"RT vencida",IF(AND(ISNUMBER($O12),$O12<0),"Gases vencidos",IF(AND(ISNUMBER($M12),$M12<=30),"RT próxima",IF(AND(ISNUMBER($O12),$O12<=30),"Gases próximos",IF(AND(ISNUMBER($Q12),$Q12<=500),"Cambio aceite próximo","OK"))))))) -> OK | Y12: =Tabla1[[#This Row],[PRIORIDAD]]+(ROW()/1000) -> 6.012
A13: TRACTOR | B13: Rulo | C13: =_xlfn.XLOOKUP(Tabla1[[#This Row],[MAQUINARIA]],Hoja3!A:A,Hoja3!C:C) -> T4 | D13: T4 | E13: New Holland | F13: T4030F | G13: 2011 | H13: CYPX-61 | I13: =SUMIF(GPS!$D13:$D$1048576,Tabla1[[#This Row],[MAQUINARIA]],GPS!$G$2:$G$1048576) -> 1158.64 | K13: =Tabla1[[#This Row],[KM]]+SUMIF(GPS!$D$746:$D$1048570,Tabla1[[#This Row],[MAQUINARIA]],GPS!$G$746:$G$1048570) -> 0 | L13: 46997 | M13: =IF(L13="-","-",L13-TODAY()) -> 786 | N13: =Tabla1[[#This Row],[REVISION TECNICA]] -> 46997 | O13: =IF(Tabla1[[#This Row],[GASES Y CONTAMINANTES]]="-","-",Tabla1[[#This Row],[GASES Y CONTAMINANTES]]-TODAY()) -> 786 | Q13: =IF(Tabla1[[#This Row],[PROXIMO Cambio de aceite]]="","-",Tabla1[[#This Row],[PROXIMO Cambio de aceite]]-Tabla1[[#This Row],[KM ACTUAL]]) -> - | R13: EN MANTENCIÓN | S13: =SUMIF(GPS!D:D,Tabla1[[#This Row],[MAQUINARIA]],GPS!M:M) -> 125408.42 | T13: =SUMIF('GASTOS Y MANTENCIONES'!B:B,C13,'GASTOS Y MANTENCIONES'!C:C) -> 37800 | U13: =Tabla1[[#This Row],[GASTO EN COMBUSTIBLES]]+Tabla1[[#This Row],[$ EN MANTENCIÓN]] -> 163208.42 | V13: =IFERROR((Tabla1[[#This Row],[GASTO EN COMBUSTIBLES]]+Tabla1[[#This Row],[$ EN MANTENCIÓN]])/Tabla1[[#This Row],[KM DE comienzo]],"-") -> 140.86206 | W13: =IF($R13="FUERA DE SERVICIO",1,IF($R13="EN MANTENCIÓN",2,IF(OR(AND(ISNUMBER($M13),$M13<0),AND(ISNUMBER($O13),$O13<0)),3,IF(OR(AND(ISNUMBER($M13),$M13<=30),AND(ISNUMBER($O13),$O13<=30)),4,IF(AND(ISNUMBER($Q13),$Q13<=10000),5,6))))) -> 2 | X13: =IF($R13="FUERA DE SERVICIO","Fuera de servicio",IF($R13="EN MANTENCIÓN","En mantención",IF(AND(ISNUMBER($M13),$M13<0),"RT vencida",IF(AND(ISNUMBER($O13),$O13<0),"Gases vencidos",IF(AND(ISNUMBER($M13),$M13<=30),"RT próxima",IF(AND(ISNUMBER($O13),$O13<=30),"Gases próximos",IF(AND(ISNUMBER($Q13),$Q13<=500),"Cambio aceite próximo","OK"))))))) -> En mantención | Y13: =Tabla1[[#This Row],[PRIORIDAD]]+(ROW()/1000) -> 2.013
A14: TRACTOR | B14: Rulo | C14: =_xlfn.XLOOKUP(Tabla1[[#This Row],[MAQUINARIA]],Hoja3!A:A,Hoja3!C:C) -> T7 | D14: T7 | E14: Same | F14: FRUTTETO3 75 | G14: 2017 | H14: JYJT-42 | I14: =SUMIF(GPS!$D14:$D$1048576,Tabla1[[#This Row],[MAQUINARIA]],GPS!$G$2:$G$1048576) -> 1578.3 | K14: =Tabla1[[#This Row],[KM]]+SUMIF(GPS!$D$746:$D$1048570,Tabla1[[#This Row],[MAQUINARIA]],GPS!$G$746:$G$1048570) -> 0 | L14: 46296 | M14: =IF(L14="-","-",L14-TODAY()) -> 85 | N14: =Tabla1[[#This Row],[REVISION TECNICA]] -> 46296 | O14: =IF(Tabla1[[#This Row],[GASES Y CONTAMINANTES]]="-","-",Tabla1[[#This Row],[GASES Y CONTAMINANTES]]-TODAY()) -> 85 | Q14: =IF(Tabla1[[#This Row],[PROXIMO Cambio de aceite]]="","-",Tabla1[[#This Row],[PROXIMO Cambio de aceite]]-Tabla1[[#This Row],[KM ACTUAL]]) -> - | R14: OPERATIVA | S14: =SUMIF(GPS!D:D,Tabla1[[#This Row],[MAQUINARIA]],GPS!M:M) -> 82748.9 | T14: =SUMIF('GASTOS Y MANTENCIONES'!B:B,C14,'GASTOS Y MANTENCIONES'!C:C) -> 37800 | U14: =Tabla1[[#This Row],[GASTO EN COMBUSTIBLES]]+Tabla1[[#This Row],[$ EN MANTENCIÓN]] -> 120548.9 | V14: =IFERROR((Tabla1[[#This Row],[GASTO EN COMBUSTIBLES]]+Tabla1[[#This Row],[$ EN MANTENCIÓN]])/Tabla1[[#This Row],[KM DE comienzo]],"-") -> 76.378952 | W14: =IF($R14="FUERA DE SERVICIO",1,IF($R14="EN MANTENCIÓN",2,IF(OR(AND(ISNUMBER($M14),$M14<0),AND(ISNUMBER($O14),$O14<0)),3,IF(OR(AND(ISNUMBER($M14),$M14<=30),AND(ISNUMBER($O14),$O14<=30)),4,IF(AND(ISNUMBER($Q14),$Q14<=10000),5,6))))) -> 6 | X14: =IF($R14="FUERA DE SERVICIO","Fuera de servicio",IF($R14="EN MANTENCIÓN","En mantención",IF(AND(ISNUMBER($M14),$M14<0),"RT vencida",IF(AND(ISNUMBER($O14),$O14<0),"Gases vencidos",IF(AND(ISNUMBER($M14),$M14<=30),"RT próxima",IF(AND(ISNUMBER($O14),$O14<=30),"Gases próximos",IF(AND(ISNUMBER($Q14),$Q14<=500),"Cambio aceite próximo","OK"))))))) -> OK | Y14: =Tabla1[[#This Row],[PRIORIDAD]]+(ROW()/1000) -> 6.014
A15: TRACTOR | B15: Rulo | C15: =_xlfn.XLOOKUP(Tabla1[[#This Row],[MAQUINARIA]],Hoja3!A:A,Hoja3!C:C) -> T5 | D15: T5 | E15: New Holland | F15: T4030FWD | G15: 2011 | H15: CYPX-60 | I15: =SUMIF(GPS!$D15:$D$1048576,Tabla1[[#This Row],[MAQUINARIA]],GPS!$G$2:$G$1048576) -> 989.03 | K15: =Tabla1[[#This Row],[KM]]+SUMIF(GPS!$D$746:$D$1048570,Tabla1[[#This Row],[MAQUINARIA]],GPS!$G$746:$G$1048570) -> 0 | L15: 46997 | M15: =IF(L15="-","-",L15-TODAY()) -> 786 | N15: =Tabla1[[#This Row],[REVISION TECNICA]] -> 46997 | O15: =IF(Tabla1[[#This Row],[GASES Y CONTAMINANTES]]="-","-",Tabla1[[#This Row],[GASES Y CONTAMINANTES]]-TODAY()) -> 786 | Q15: =IF(Tabla1[[#This Row],[PROXIMO Cambio de aceite]]="","-",Tabla1[[#This Row],[PROXIMO Cambio de aceite]]-Tabla1[[#This Row],[KM ACTUAL]]) -> - | R15: OPERATIVA | S15: =SUMIF(GPS!D:D,Tabla1[[#This Row],[MAQUINARIA]],GPS!M:M) -> 76049.322 | T15: =SUMIF('GASTOS Y MANTENCIONES'!B:B,C15,'GASTOS Y MANTENCIONES'!C:C) -> 37800 | U15: =Tabla1[[#This Row],[GASTO EN COMBUSTIBLES]]+Tabla1[[#This Row],[$ EN MANTENCIÓN]] -> 113849.32 | V15: =IFERROR((Tabla1[[#This Row],[GASTO EN COMBUSTIBLES]]+Tabla1[[#This Row],[$ EN MANTENCIÓN]])/Tabla1[[#This Row],[KM DE comienzo]],"-") -> 115.1121 | W15: =IF($R15="FUERA DE SERVICIO",1,IF($R15="EN MANTENCIÓN",2,IF(OR(AND(ISNUMBER($M15),$M15<0),AND(ISNUMBER($O15),$O15<0)),3,IF(OR(AND(ISNUMBER($M15),$M15<=30),AND(ISNUMBER($O15),$O15<=30)),4,IF(AND(ISNUMBER($Q15),$Q15<=10000),5,6))))) -> 6 | X15: =IF($R15="FUERA DE SERVICIO","Fuera de servicio",IF($R15="EN MANTENCIÓN","En mantención",IF(AND(ISNUMBER($M15),$M15<0),"RT vencida",IF(AND(ISNUMBER($O15),$O15<0),"Gases vencidos",IF(AND(ISNUMBER($M15),$M15<=30),"RT próxima",IF(AND(ISNUMBER($O15),$O15<=30),"Gases próximos",IF(AND(ISNUMBER($Q15),$Q15<=500),"Cambio aceite próximo","OK"))))))) -> OK | Y15: =Tabla1[[#This Row],[PRIORIDAD]]+(ROW()/1000) -> 6.015
A16: TRACTOR | B16: Cerrillos | C16: =_xlfn.XLOOKUP(Tabla1[[#This Row],[MAQUINARIA]],Hoja3!A:A,Hoja3!C:C) -> T12 | D16: T12 | E16: John Deere | F16: 5085GL | G16: 2021 | H16: LZPF54 | I16: =SUMIF(GPS!$D16:$D$1048576,Tabla1[[#This Row],[MAQUINARIA]],GPS!$G$2:$G$1048576) -> 931.65 | K16: =Tabla1[[#This Row],[KM]]+SUMIF(GPS!$D$746:$D$1048570,Tabla1[[#This Row],[MAQUINARIA]],GPS!$G$746:$G$1048570) -> 0 | L16: 45901 | M16: =IF(L16="-","-",L16-TODAY()) -> -310 | N16: =Tabla1[[#This Row],[REVISION TECNICA]] -> 45901 | O16: =IF(Tabla1[[#This Row],[GASES Y CONTAMINANTES]]="-","-",Tabla1[[#This Row],[GASES Y CONTAMINANTES]]-TODAY()) -> -310 | Q16: =IF(Tabla1[[#This Row],[PROXIMO Cambio de aceite]]="","-",Tabla1[[#This Row],[PROXIMO Cambio de aceite]]-Tabla1[[#This Row],[KM ACTUAL]]) -> - | R16: OPERATIVA | S16: =SUMIF(GPS!D:D,Tabla1[[#This Row],[MAQUINARIA]],GPS!M:M) -> 74638.147 | T16: =SUMIF('GASTOS Y MANTENCIONES'!B:B,C16,'GASTOS Y MANTENCIONES'!C:C) -> 37800 | U16: =Tabla1[[#This Row],[GASTO EN COMBUSTIBLES]]+Tabla1[[#This Row],[$ EN MANTENCIÓN]] -> 112438.15 | V16: =IFERROR((Tabla1[[#This Row],[GASTO EN COMBUSTIBLES]]+Tabla1[[#This Row],[$ EN MANTENCIÓN]])/Tabla1[[#This Row],[KM DE comienzo]],"-") -> 120.68711 | W16: =IF($R16="FUERA DE SERVICIO",1,IF($R16="EN MANTENCIÓN",2,IF(OR(AND(ISNUMBER($M16),$M16<0),AND(ISNUMBER($O16),$O16<0)),3,IF(OR(AND(ISNUMBER($M16),$M16<=30),AND(ISNUMBER($O16),$O16<=30)),4,IF(AND(ISNUMBER($Q16),$Q16<=10000),5,6))))) -> 3 | X16: =IF($R16="FUERA DE SERVICIO","Fuera de servicio",IF($R16="EN MANTENCIÓN","En mantención",IF(AND(ISNUMBER($M16),$M16<0),"RT vencida",IF(AND(ISNUMBER($O16),$O16<0),"Gases vencidos",IF(AND(ISNUMBER($M16),$M16<=30),"RT próxima",IF(AND(ISNUMBER($O16),$O16<=30),"Gases próximos",IF(AND(ISNUMBER($Q16),$Q16<=500),"Cambio aceite próximo","OK"))))))) -> RT vencida | Y16: =Tabla1[[#This Row],[PRIORIDAD]]+(ROW()/1000) -> 3.016
A17: TRACTOR | B17: Rulo | C17: =_xlfn.XLOOKUP(Tabla1[[#This Row],[MAQUINARIA]],Hoja3!A:A,Hoja3!C:C) -> T6 | D17: T6 | E17: New Holland | F17: T4040F W FRUTER | G17: 2013 | H17: FDHD-57 | I17: =SUMIF(GPS!$D17:$D$1048576,Tabla1[[#This Row],[MAQUINARIA]],GPS!$G$2:$G$1048576) -> 897.88 | K17: =Tabla1[[#This Row],[KM]]+SUMIF(GPS!$D$746:$D$1048570,Tabla1[[#This Row],[MAQUINARIA]],GPS!$G$746:$G$1048570) -> 0 | L17: 46997 | M17: =IF(L17="-","-",L17-TODAY()) -> 786 | N17: =Tabla1[[#This Row],[REVISION TECNICA]] -> 46997 | O17: =IF(Tabla1[[#This Row],[GASES Y CONTAMINANTES]]="-","-",Tabla1[[#This Row],[GASES Y CONTAMINANTES]]-TODAY()) -> 786 | Q17: =IF(Tabla1[[#This Row],[PROXIMO Cambio de aceite]]="","-",Tabla1[[#This Row],[PROXIMO Cambio de aceite]]-Tabla1[[#This Row],[KM ACTUAL]]) -> - | R17: OPERATIVA | S17: =SUMIF(GPS!D:D,Tabla1[[#This Row],[MAQUINARIA]],GPS!M:M) -> 74143.735 | T17: =SUMIF('GASTOS Y MANTENCIONES'!B:B,C17,'GASTOS Y MANTENCIONES'!C:C) -> 37800 | U17: =Tabla1[[#This Row],[GASTO EN COMBUSTIBLES]]+Tabla1[[#This Row],[$ EN MANTENCIÓN]] -> 111943.73 | V17: =IFERROR((Tabla1[[#This Row],[GASTO EN COMBUSTIBLES]]+Tabla1[[#This Row],[$ EN MANTENCIÓN]])/Tabla1[[#This Row],[KM DE comienzo]],"-") -> 124.67561 | W17: =IF($R17="FUERA DE SERVICIO",1,IF($R17="EN MANTENCIÓN",2,IF(OR(AND(ISNUMBER($M17),$M17<0),AND(ISNUMBER($O17),$O17<0)),3,IF(OR(AND(ISNUMBER($M17),$M17<=30),AND(ISNUMBER($O17),$O17<=30)),4,IF(AND(ISNUMBER($Q17),$Q17<=10000),5,6))))) -> 6 | X17: =IF($R17="FUERA DE SERVICIO","Fuera de servicio",IF($R17="EN MANTENCIÓN","En mantención",IF(AND(ISNUMBER($M17),$M17<0),"RT vencida",IF(AND(ISNUMBER($O17),$O17<0),"Gases vencidos",IF(AND(ISNUMBER($M17),$M17<=30),"RT próxima",IF(AND(ISNUMBER($O17),$O17<=30),"Gases próximos",IF(AND(ISNUMBER($Q17),$Q17<=500),"Cambio aceite próximo","OK"))))))) -> OK | Y17: =Tabla1[[#This Row],[PRIORIDAD]]+(ROW()/1000) -> 6.017
A18: TRACTOR | B18: Paine | C18: =_xlfn.XLOOKUP(Tabla1[[#This Row],[MAQUINARIA]],Hoja3!A:A,Hoja3!C:C) -> T10 | D18: T10 | E18: Kubota | F18: M8540DTN | G18: 2020 | H18: LWTR75 | I18: =SUMIF(GPS!$D18:$D$1048576,Tabla1[[#This Row],[MAQUINARIA]],GPS!$G$2:$G$1048576) -> 707.55 | K18: =Tabla1[[#This Row],[KM]]+SUMIF(GPS!$D$746:$D$1048570,Tabla1[[#This Row],[MAQUINARIA]],GPS!$G$746:$G$1048570) -> 0 | L18: 46997 | M18: =IF(L18="-","-",L18-TODAY()) -> 786 | N18: =Tabla1[[#This Row],[REVISION TECNICA]] -> 46997 | O18: =IF(Tabla1[[#This Row],[GASES Y CONTAMINANTES]]="-","-",Tabla1[[#This Row],[GASES Y CONTAMINANTES]]-TODAY()) -> 786 | Q18: =IF(Tabla1[[#This Row],[PROXIMO Cambio de aceite]]="","-",Tabla1[[#This Row],[PROXIMO Cambio de aceite]]-Tabla1[[#This Row],[KM ACTUAL]]) -> - | R18: OPERATIVA | S18: =SUMIF(GPS!D:D,Tabla1[[#This Row],[MAQUINARIA]],GPS!M:M) -> 73128.89 | T18: =SUMIF('GASTOS Y MANTENCIONES'!B:B,C18,'GASTOS Y MANTENCIONES'!C:C) -> 37800 | U18: =Tabla1[[#This Row],[GASTO EN COMBUSTIBLES]]+Tabla1[[#This Row],[$ EN MANTENCIÓN]] -> 110928.89 | V18: =IFERROR((Tabla1[[#This Row],[GASTO EN COMBUSTIBLES]]+Tabla1[[#This Row],[$ EN MANTENCIÓN]])/Tabla1[[#This Row],[KM DE comienzo]],"-") -> 156.77887 | W18: =IF($R18="FUERA DE SERVICIO",1,IF($R18="EN MANTENCIÓN",2,IF(OR(AND(ISNUMBER($M18),$M18<0),AND(ISNUMBER($O18),$O18<0)),3,IF(OR(AND(ISNUMBER($M18),$M18<=30),AND(ISNUMBER($O18),$O18<=30)),4,IF(AND(ISNUMBER($Q18),$Q18<=10000),5,6))))) -> 6 | X18: =IF($R18="FUERA DE SERVICIO","Fuera de servicio",IF($R18="EN MANTENCIÓN","En mantención",IF(AND(ISNUMBER($M18),$M18<0),"RT vencida",IF(AND(ISNUMBER($O18),$O18<0),"Gases vencidos",IF(AND(ISNUMBER($M18),$M18<=30),"RT próxima",IF(AND(ISNUMBER($O18),$O18<=30),"Gases próximos",IF(AND(ISNUMBER($Q18),$Q18<=500),"Cambio aceite próximo","OK"))))))) -> OK | Y18: =Tabla1[[#This Row],[PRIORIDAD]]+(ROW()/1000) -> 6.018
A19: TRACTOR | B19: Cerrillos | C19: =_xlfn.XLOOKUP(Tabla1[[#This Row],[MAQUINARIA]],Hoja3!A:A,Hoja3!C:C) -> T8 | D19: T8 | E19: Same | F19: FRUTTETO3 75 | G19: 2017 | H19: JYJT-41 | I19: =SUMIF(GPS!$D19:$D$1048576,Tabla1[[#This Row],[MAQUINARIA]],GPS!$G$2:$G$1048576) -> 933.11 | K19: =Tabla1[[#This Row],[KM]]+SUMIF(GPS!$D$746:$D$1048570,Tabla1[[#This Row],[MAQUINARIA]],GPS!$G$746:$G$1048570) -> 0 | L19: 46296 | M19: =IF(L19="-","-",L19-TODAY()) -> 85 | N19: =Tabla1[[#This Row],[REVISION TECNICA]] -> 46296 | O19: =IF(Tabla1[[#This Row],[GASES Y CONTAMINANTES]]="-","-",Tabla1[[#This Row],[GASES Y CONTAMINANTES]]-TODAY()) -> 85 | Q19: =IF(Tabla1[[#This Row],[PROXIMO Cambio de aceite]]="","-",Tabla1[[#This Row],[PROXIMO Cambio de aceite]]-Tabla1[[#This Row],[KM ACTUAL]]) -> - | R19: OPERATIVA | S19: =SUMIF(GPS!D:D,Tabla1[[#This Row],[MAQUINARIA]],GPS!M:M) -> 71373.428 | T19: =SUMIF('GASTOS Y MANTENCIONES'!B:B,C19,'GASTOS Y MANTENCIONES'!C:C) -> 37800 | U19: =Tabla1[[#This Row],[GASTO EN COMBUSTIBLES]]+Tabla1[[#This Row],[$ EN MANTENCIÓN]] -> 109173.43 | V19: =IFERROR((Tabla1[[#This Row],[GASTO EN COMBUSTIBLES]]+Tabla1[[#This Row],[$ EN MANTENCIÓN]])/Tabla1[[#This Row],[KM DE comienzo]],"-") -> 116.99953 | W19: =IF($R19="FUERA DE SERVICIO",1,IF($R19="EN MANTENCIÓN",2,IF(OR(AND(ISNUMBER($M19),$M19<0),AND(ISNUMBER($O19),$O19<0)),3,IF(OR(AND(ISNUMBER($M19),$M19<=30),AND(ISNUMBER($O19),$O19<=30)),4,IF(AND(ISNUMBER($Q19),$Q19<=10000),5,6))))) -> 6 | X19: =IF($R19="FUERA DE SERVICIO","Fuera de servicio",IF($R19="EN MANTENCIÓN","En mantención",IF(AND(ISNUMBER($M19),$M19<0),"RT vencida",IF(AND(ISNUMBER($O19),$O19<0),"Gases vencidos",IF(AND(ISNUMBER($M19),$M19<=30),"RT próxima",IF(AND(ISNUMBER($O19),$O19<=30),"Gases próximos",IF(AND(ISNUMBER($Q19),$Q19<=500),"Cambio aceite próximo","OK"))))))) -> OK | Y19: =Tabla1[[#This Row],[PRIORIDAD]]+(ROW()/1000) -> 6.019
A20: TRACTOR | B20: Cerrillos | C20: =_xlfn.XLOOKUP(Tabla1[[#This Row],[MAQUINARIA]],Hoja3!A:A,Hoja3!C:C) -> T11 | D20: T11 | E20: John Deere | F20: 5085GL | G20: 2021 | H20: LXFB96 | I20: =SUMIF(GPS!$D20:$D$1048576,Tabla1[[#This Row],[MAQUINARIA]],GPS!$G$2:$G$1048576) -> 898.3 | K20: =Tabla1[[#This Row],[KM]]+SUMIF(GPS!$D$746:$D$1048570,Tabla1[[#This Row],[MAQUINARIA]],GPS!$G$746:$G$1048570) -> 0 | L20: 45901 | M20: =IF(L20="-","-",L20-TODAY()) -> -310 | N20: =Tabla1[[#This Row],[REVISION TECNICA]] -> 45901 | O20: =IF(Tabla1[[#This Row],[GASES Y CONTAMINANTES]]="-","-",Tabla1[[#This Row],[GASES Y CONTAMINANTES]]-TODAY()) -> -310 | Q20: =IF(Tabla1[[#This Row],[PROXIMO Cambio de aceite]]="","-",Tabla1[[#This Row],[PROXIMO Cambio de aceite]]-Tabla1[[#This Row],[KM ACTUAL]]) -> - | R20: OPERATIVA | S20: =SUMIF(GPS!D:D,Tabla1[[#This Row],[MAQUINARIA]],GPS!M:M) -> 62267.847 | T20: =SUMIF('GASTOS Y MANTENCIONES'!B:B,C20,'GASTOS Y MANTENCIONES'!C:C) -> 37800 | U20: =Tabla1[[#This Row],[GASTO EN COMBUSTIBLES]]+Tabla1[[#This Row],[$ EN MANTENCIÓN]] -> 100067.85 | V20: =IFERROR((Tabla1[[#This Row],[GASTO EN COMBUSTIBLES]]+Tabla1[[#This Row],[$ EN MANTENCIÓN]])/Tabla1[[#This Row],[KM DE comienzo]],"-") -> 111.39691 | W20: =IF($R20="FUERA DE SERVICIO",1,IF($R20="EN MANTENCIÓN",2,IF(OR(AND(ISNUMBER($M20),$M20<0),AND(ISNUMBER($O20),$O20<0)),3,IF(OR(AND(ISNUMBER($M20),$M20<=30),AND(ISNUMBER($O20),$O20<=30)),4,IF(AND(ISNUMBER($Q20),$Q20<=10000),5,6))))) -> 3 | X20: =IF($R20="FUERA DE SERVICIO","Fuera de servicio",IF($R20="EN MANTENCIÓN","En mantención",IF(AND(ISNUMBER($M20),$M20<0),"RT vencida",IF(AND(ISNUMBER($O20),$O20<0),"Gases vencidos",IF(AND(ISNUMBER($M20),$M20<=30),"RT próxima",IF(AND(ISNUMBER($O20),$O20<=30),"Gases próximos",IF(AND(ISNUMBER($Q20),$Q20<=500),"Cambio aceite próximo","OK"))))))) -> RT vencida | Y20: =Tabla1[[#This Row],[PRIORIDAD]]+(ROW()/1000) -> 3.02
